Workbook
Name _Toc209908: BP_Pres!#REF!
Name _Toc209939: BP_Pres!$A$157
Name _Toc209949: BP_Pres!$A$165
Name _Toc209956: BP_Pres!$A$223
Name _Toc209961: BP_Pres!$A$297
Name _Toc209965: BP_Pres!$A$369
Name _Toc3199075: BP_Pres!$A$98
Name _Toc3199076: BP_Pres!$A$125
Name _Toc3199077: BP_Pres!$A$126
Name _Toc3199078: BP_Pres!$A$130
Name _Toc3199080: BP_Pres!$A$160
Name _Toc3199082: BP_Pres!#REF!
Name _Toc3199083: BP_Pres!$A$167
Name _Toc3199084: BP_Pres!$A$199
Name _Toc3199085: BP_Pres!$A$200
Name _Toc3199086: BP_Pres!$A$211
Name _Toc3199088: BP_Pres!$A$224
Name _Toc3199089: BP_Pres!$A$252
Name _Toc3199090: BP_Pres!$A$269
Name _Toc3199091: BP_Pres!$A$297
Name _Toc3199092: BP_Pres!$A$298
Name _Toc3199093: BP_Pres!$A$346
Name _Toc959083: BP_Pres!$A$262
Name Debt_Choice: #REF!
Name jj: #REF!
Name valuevx: 42.314159

Sheet BP_Pres
A2: Instructions:
A3: 1. Remplir les données concernant les "variables principales". Les calculs se font automatiquement.
A4: 2. Remplir les informations sur le promoteur aux pages 1 et 3.
A5: 3. Imprimer
A9: Variables principales pour le client final
A10: Type de produit | B10: Nom | C10: Qté | D10: Prix
A11: Ventes de marchandises | B11: {var_1} | C11: {var_5} | D11: {var_9}
A12: Ventes de marchandises | B12: {var_2} | C12: {var_6} | D12: {var_10}
A13: Ventes de marchandises | B13: {var_3} | C13: {var_7} | D13: {var_12}
A14: Ventes de marchandises | B14: {var_4} | C14: {var_8} | D14: {var_13} | E14: {var_11}
A76: Table des matières
A77: RÉSUMÉ DU PROJET | G77: 3
A78: 1. | B78: DESCRIPTION DU PROJET | G78: 4
A79: 2. | B79: MOYENS MATÉRIELS ET HUMAINS | G79: 4
A80: 3. | B80: PROGRAMME DE RÉALISATION | G80: 4
A81: 4. | B81: DESCRIPTION DU MARCHE | G81: 5
A82: 5. | B82: ÉTUDE FINANCIÈRE ET PLAN DE FINANCEMENT | G82: 5
A83: 5.1 | B83: Investissements | G83: 5
A84: 5.2 | B84: Fonds de Roulement | G84: 5
A85: 5.3 | B85: Récapitulatif des besoins de financement | G85: 6
A86: 5.4 | B86: Prévision des recettes | G86: 7
A87: 6. | B87: LES CHARGES D’EXPLOITATION | G87: 8
A88: 6.1 | B88: Achats, services extérieurs et autres charges | G88: 8
A89: 6.2 | B89: Impôts annuels et frais financiers | G89: 9
... A95: 7.4 | B95: Bilan annuel prévisionnel | G95: 14
A98: RÉSUMÉ DU PROJET
A100: NOM DU BÉNÉFICIAIRE :
A101: Ce simulateur de business plan s'adresse principalement aux promotteurs qui souhaitent vendre en gros des vêtements, des matériaux de construction, des voitures… Il reprend un circuit classique d'importation par container et de revente du contenu du container aux clients grossistes.
A102: Ø Nom et prénoms :
A103: Ø Date et lieu de naissance :
A104: Ø Sexe :
A105: Ø Situation Matrimoniale :
A106: Ø Niveau d’étude et diplôme :
A107: Ø Téléphone :
A108: Ø Adresse géographique :
B109: Année 1 | C109: Année 2 | D109: Année 3 | E109: Année 4 | F109: Année 5 | G109: Total
A110: Financement total requis | B110: =SUM(B111,B112,B116) -> 3775000.9 | C110: =SUM(C111,C112,C116) -> 3698500.9 | D110: =SUM(D111,D112,D116) -> 0 | E110: =SUM(E111,E112,E116) -> 0 | F110: =SUM(F111,F112,F116) -> 0 | G110: =SUM(B110:F110) -> 7473501.7
A111: Capital initial | B111: ='1.Var.Fin'!B17 -> 0 | C111: ='1.Var.Fin'!C17 -> 0 | D111: ='1.Var.Fin'!D17 -> 0 | E111: ='1.Var.Fin'!E17 -> 0 | F111: ='1.Var.Fin'!F17 -> 0 | G111: =SUM(B111:F111) -> 0
A112: Emprunt à court terme (BFR, achat…) | B112: ='1.Var.Fin'!B11 -> 3698500.9 | C112: ='1.Var.Fin'!C11 -> 0 | D112: ='1.Var.Fin'!D11 -> 0 | E112: ='1.Var.Fin'!E11 -> 0 | F112: ='1.Var.Fin'!F11 -> 0 | G112: =SUM(B112:F112) -> 3698500.9
A113: Durée (mois) | B113: ='1.Var.Fin'!B14 -> 12 | C113: ='1.Var.Fin'!C14 -> 12 | D113: ='1.Var.Fin'!D14 -> 12 | E113: ='1.Var.Fin'!E14 -> 0 | F113: ='1.Var.Fin'!F14 -> 0 | G113: =AVERAGE(B113:F113) -> 7.2
...

Sheet LiensFeuilles
A1: Liens entre les feuilles de calcul

Sheet 1.Var.Fin
A1: FACTEURS DE VARIATION AMORTISSEMENT FINANCIER
A2: Variables financières
B3: Année 1 | C3: Année 2 | D3: Année 3
A4: Emprunt à long terme
A5: Montant | B5: =SUMIF('21.BFR'!$F$3:$F$41,'1.Var.Fin'!B6,'21.BFR'!$G$3:$G$41)+SUMIF('7.Bud.Inv.'!$D$3:$D$22,'1.Var.Fin'!B6,'7.Bud.Inv.'!$Q$3:$Q$22) -> 76500 | C5: =SUMIF('21.BFR'!$F$3:$F$41,'1.Var.Fin'!C6,'21.BFR'!$G$3:$G$41)+SUMIF('7.Bud.Inv.'!$D$3:$D$22,'1.Var.Fin'!C6,'7.Bud.Inv.'!$Q$3:$Q$22) -> 3698500.9 | D5: =SUMIF('21.BFR'!$F$3:$F$41,'1.Var.Fin'!D6,'21.BFR'!$G$3:$G$41)+SUMIF('7.Bud.Inv.'!$D$3:$D$22,'1.Var.Fin'!D6,'7.Bud.Inv.'!$Q$3:$Q$22) -> 0
A6: Code financement | B6: EMP1 | C6: EMP2 | D6: EMP3
A7: Taux d'intérêt | B7: 0.09 | C7: 0.11 | D7: 0.1
A8: Nb de mois | B8: 36 | C8: 36 | D8: 36
A9: TOB | B9: 0.1 | C9: 1.1 | D9: 2.1
A10: Emprunt à court terme
A11: Montant | B11: =SUMIF('21.BFR'!$F$3:$F$41,'1.Var.Fin'!B12,'21.BFR'!$G$3:$G$41)+SUMIF('7.Bud.Inv.'!$D$3:$D$22,'1.Var.Fin'!B12,'7.Bud.Inv.'!$Q$3:$Q$22) -> 3698500.9 | C11: =SUMIF('21.BFR'!$F$3:$F$41,'1.Var.Fin'!C12,'21.BFR'!$G$3:$G$41)+SUMIF('7.Bud.Inv.'!$D$3:$D$22,'1.Var.Fin'!C12,'7.Bud.Inv.'!$Q$3:$Q$22) -> 0 | D11: =SUMIF('21.BFR'!$F$3:$F$41,'1.Var.Fin'!D12,'21.BFR'!$G$3:$G$41)+SUMIF('7.Bud.Inv.'!$D$3:$D$22,'1.Var.Fin'!D12,'7.Bud.Inv.'!$Q$3:$Q$22) -> 0
A12: Code financement | B12: EMP2 | C12: EMP3 | D12: EMP4
A13: Taux d'intérêt | B13: 0.14 | C13: 0.14 | D13: 0.14
A14: Nb de mois | B14: 12 | C14: 12 | D14: 12
A15: TOB | B15: 0.1 | C15: 0.1 | D15: 0.1
A16: Apport initial (Compte courant)
A17: Montant | B17: =SUMIF('21.BFR'!$F$3:$F$41,'1.Var.Fin'!B18,'21.BFR'!$G$3:$G$41)+SUMIF('7.Bud.Inv.'!$D$3:$D$22,'1.Var.Fin'!B18,'7.Bud.Inv.'!$Q$3:$Q$22) -> 0 | C17: =SUMIF('21.BFR'!$F$3:$F$41,'1.Var.Fin'!C18,'21.BFR'!$G$3:$G$41)+SUMIF('7.Bud.Inv.'!$D$3:$D$22,'1.Var.Fin'!C18,'7.Bud.Inv.'!$Q$3:$Q$22) -> 0 | D17: =SUMIF('21.BFR'!$F$3:$F$41,'1.Var.Fin'!D18,'21.BFR'!$G$3:$G$41)+SUMIF('7.Bud.Inv.'!$D$3:$D$22,'1.Var.Fin'!D18,'7.Bud.Inv.'!$Q$3:$Q$22) -> 0
A18: Code financement | B18: EMP3 | C18: EMP3 | D18: EMP3
A19: Taux d'intérêt | B19: 0 | C19: 0 | D19: 0
A20: Nb de mois | B20: 36 | C20: 36 | D20: 36
A21: TOB | B21: 0.1 | C21: 0.1 | D21: 0.1

Sheet 2.Cal.Amo.CT
A1: TABLEAU D'AMORTISSEMENT EMPRUNT A COURT TERME
A3: Année 1
A4: Emprunt | B4: ='1.Var.Fin'!B11 -> 3698500.9
A5: Taux Annuel | B5: =+'1.Var.Fin'!B13 -> 0.14
A6: Taux effectif mensuel | B6: =B5/12 -> 0.011666667
A7: TOB | B7: ='1.Var.Fin'!B9 -> 0.1 | E7: Montant (FCFA)
A8: Durée | B8: ='1.Var.Fin'!B14 -> 12 | C8: Mois
A9: Mois | B9: Capital restant | C9: INTERET | D9: TOB | E9: Amortissement | F9: Mensualité | G9: ANNEE
A10: 1 | B10: =B4 -> 3698500.9 | C10: =B10*$B$6 -> 43149.177 | D10: =C10*$B$7 -> 4314.9177 | E10: =IFERROR(F10-C10,"") -> 288928.56 | F10: =IF(B10>1,IFERROR(($B$4*$B$6/((1-(1+$B$6)^(-$B$8)))),""),0) -> 332077.73 | G10: N
A11: 2 | B11: =IFERROR(B10-E10, "") -> 3409572.3 | C11: =B11*$B$6 -> 39778.344 | D11: =C11*$B$7 -> 3977.8344 | E11: =IFERROR(F11-C11,"") -> 292299.39 | F11: =IF(B11>1,IFERROR(($B$4*$B$6/((1-(1+$B$6)^(-$B$8)))),""),0) -> 332077.73 | G11: N
A12: 3 | B12: =IFERROR(B11-E11, "") -> 3117272.9 | C12: =B12*$B$6 -> 36368.184 | D12: =C12*$B$7 -> 3636.8184 | E12: =IFERROR(F12-C12,"") -> 295709.55 | F12: =IF(B12>1,IFERROR(($B$4*$B$6/((1-(1+$B$6)^(-$B$8)))),""),0) -> 332077.73 | G12: N
A13: 4 | B13: =IFERROR(B12-E12, "") -> 2821563.4 | C13: =B13*$B$6 -> 32918.239 | D13: =C13*$B$7 -> 3291.8239 | E13: =IFERROR(F13-C13,"") -> 299159.49 | F13: =IF(B13>1,IFERROR(($B$4*$B$6/((1-(1+$B$6)^(-$B$8)))),""),0) -> 332077.73 | G13: N
A14: 5 | B14: =IFERROR(B13-E13, "") -> 2522403.9 | C14: =B14*$B$6 -> 29428.045 | D14: =C14*$B$7 -> 2942.8045 | E14: =IFERROR(F14-C14,"") -> 302649.69 | F14: =IF(B14>1,IFERROR(($B$4*$B$6/((1-(1+$B$6)^(-$B$8)))),""),0) -> 332077.73 | G14: N
A15: 6 | B15: =IFERROR(B14-E14, "") -> 2219754.2 | C15: =B15*$B$6 -> 25897.132 | D15: =C15*$B$7 -> 2589.7132 | E15: =IFERROR(F15-C15,"") -> 306180.6 | F15: =IF(B15>1,IFERROR(($B$4*$B$6/((1-(1+$B$6)^(-$B$8)))),""),0) -> 332077.73 | G15: N
A16: 7 | B16: =IFERROR(B15-E15, "") -> 1913573.6 | C16: =B16*$B$6 -> 22325.025 | D16: =C16*$B$7 -> 2232.5025 | E16: =IFERROR(F16-C16,"") -> 309752.71 | F16: =IF(B16>1,IFERROR(($B$4*$B$6/((1-(1+$B$6)^(-$B$8)))),""),0) -> 332077.73 | G16: N
A17: 8 | B17: =IFERROR(B16-E16, "") -> 1603820.9 | C17: =B17*$B$6 -> 18711.244 | D17: =C17*$B$7 -> 1871.1244 | E17: =IFERROR(F17-C17,"") -> 313366.49 | F17: =IF(B17>1,IFERROR(($B$4*$B$6/((1-(1+$B$6)^(-$B$8)))),""),0) -> 332077.73 | G17: N
A18: 9 | B18: =IFERROR(B17-E17, "") -> 1290454.4 | C18: =B18*$B$6 -> 15055.301 | D18: =C18*$B$7 -> 1505.5301 | E18: =IFERROR(F18-C18,"") -> 317022.43 | F18: =IF(B18>1,IFERROR(($B$4*$B$6/((1-(1+$B$6)^(-$B$8)))),""),0) -> 332077.73 | G18: N
A19: 10 | B19: =IFERROR(B18-E18, "") -> 973431.97 | C19: =B19*$B$6 -> 11356.706 | D19: =C19*$B$7 -> 1135.6706 | E19: =IFERROR(F19-C19,"") -> 320721.03 | F19: =IF(B19>1,IFERROR(($B$4*$B$6/((1-(1+$B$6)^(-$B$8)))),""),0) -> 332077.73 | G19: N
A20: 11 | B20: =IFERROR(B19-E19, "") -> 652710.94 | C20: =B20*$B$6 -> 7614.961 | D20: =C20*$B$7 -> 761.4961 | E20: =IFERROR(F20-C20,"") -> 324462.77 | F20: =IF(B20>1,IFERROR(($B$4*$B$6/((1-(1+$B$6)^(-$B$8)))),""),0) -> 332077.73 | G20: N
A21: 12 | B21: =IFERROR(B20-E20, "") -> 328248.17 | C21: =B21*$B$6 -> 3829.562 | D21: =C21*$B$7 -> 382.9562 | E21: =IFERROR(F21-C21,"") -> 328248.17 | F21: =IF(B21>1,IFERROR(($B$4*$B$6/((1-(1+$B$6)^(-$B$8)))),""),0) -> 332077.73 | G21: N
A22: Année 2
A23: Emprunt | B23: ='1.Var.Fin'!C11 -> 0
A24: Taux Annuel | B24: =+'1.Var.Fin'!C13 -> 0.14
A25: Taux effectif mensuel | B25: =B24/12 -> 0.011666667
A26: TOB | B26: ='1.Var.Fin'!C9 -> 1.1 | E26: Montant (FCFA)
A27: Durée | B27: ='1.Var.Fin'!C14 -> 12 | C27: Mois
A28: Mois | B28: Capital restant | C28: INTERET | D28: TOB | E28: Amortissement | F28: Mensualité | G28: ANNEE
A29: 1 | B29: =H23 -> 0 | C29: =B29*$B$6 -> 0 | D29: =C29*$B$7 -> 0 | E29: =IFERROR(F29-C29,"") -> 0 | F29: =IF(B29>1,IFERROR(($B$4*$B$6/((1-(1+$B$6)^(-$B$8)))),""),0) -> 0 | G29: N+1
A30: 2 | B30: =IFERROR(B29-E29, "") -> 0 | C30: =B30*$B$6 -> 0 | D30: =C30*$B$7 -> 0 | E30: =IFERROR(F30-C30,"") -> 0 | F30: =IF(B30>1,IFERROR(($B$4*$B$6/((1-(1+$B$6)^(-$B$8)))),""),0) -> 0 | G30: N+1
A31: 3 | B31: =IFERROR(B30-E30, "") -> 0 | C31: =B31*$B$6 -> 0 | D31: =C31*$B$7 -> 0 | E31: =IFERROR(F31-C31,"") -> 0 | F31: =IF(B31>1,IFERROR(($B$4*$B$6/((1-(1+$B$6)^(-$B$8)))),""),0) -> 0 | G31: N+1
A32: 4 | B32: =IFERROR(B31-E31, "") -> 0 | C32: =B32*$B$6 -> 0 | D32: =C32*$B$7 -> 0 | E32: =IFERROR(F32-C32,"") -> 0 | F32: =IF(B32>1,IFERROR(($B$4*$B$6/((1-(1+$B$6)^(-$B$8)))),""),0) -> 0 | G32: N+1
A33: 5 | B33: =IFERROR(B32-E32, "") -> 0 | C33: =B33*$B$6 -> 0 | D33: =C33*$B$7 -> 0 | E33: =IFERROR(F33-C33,"") -> 0 | F33: =IF(B33>1,IFERROR(($B$4*$B$6/((1-(1+$B$6)^(-$B$8)))),""),0) -> 0 | G33: N+1
A34: 6 | B34: =IFERROR(B33-E33, "") -> 0 | C34: =B34*$B$6 -> 0 | D34: =C34*$B$7 -> 0 | E34: =IFERROR(F34-C34,"") -> 0 | F34: =IF(B34>1,IFERROR(($B$4*$B$6/((1-(1+$B$6)^(-$B$8)))),""),0) -> 0 | G34: N+1
A35: 7 | B35: =IFERROR(B34-E34, "") -> 0 | C35: =B35*$B$6 -> 0 | D35: =C35*$B$7 -> 0 | E35: =IFERROR(F35-C35,"") -> 0 | F35: =IF(B35>1,IFERROR(($B$4*$B$6/((1-(1+$B$6)^(-$B$8)))),""),0) -> 0 | G35: N+1
A36: 8 | B36: =IFERROR(B35-E35, "") -> 0 | C36: =B36*$B$6 -> 0 | D36: =C36*$B$7 -> 0 | E36: =IFERROR(F36-C36,"") -> 0 | F36: =IF(B36>1,IFERROR(($B$4*$B$6/((1-(1+$B$6)^(-$B$8)))),""),0) -> 0 | G36: N+1
A37: 9 | B37: =IFERROR(B36-E36, "") -> 0 | C37: =B37*$B$6 -> 0 | D37: =C37*$B$7 -> 0 | E37: =IFERROR(F37-C37,"") -> 0 | F37: =IF(B37>1,IFERROR(($B$4*$B$6/((1-(1+$B$6)^(-$B$8)))),""),0) -> 0 | G37: N+1
A38: 10 | B38: =IFERROR(B37-E37, "") -> 0 | C38: =B38*$B$6 -> 0 | D38: =C38*$B$7 -> 0 | E38: =IFERROR(F38-C38,"") -> 0 | F38: =IF(B38>1,IFERROR(($B$4*$B$6/((1-(1+$B$6)^(-$B$8)))),""),0) -> 0 | G38: N+1
A39: 11 | B39: =IFERROR(B38-E38, "") -> 0 | C39: =B39*$B$6 -> 0 | D39: =C39*$B$7 -> 0 | E39: =IFERROR(F39-C39,"") -> 0 | F39: =IF(B39>1,IFERROR(($B$4*$B$6/((1-(1+$B$6)^(-$B$8)))),""),0) -> 0 | G39: N+1
A40: 12 | B40: =IFERROR(B39-E39, "") -> 0 | C40: =B40*$B$6 -> 0 | D40: =C40*$B$7 -> 0 | E40: =IFERROR(F40-C40,"") -> 0 | F40: =IF(B40>1,IFERROR(($B$4*$B$6/((1-(1+$B$6)^(-$B$8)))),""),0) -> 0 | G40: N+1
A41: Année 3
...

Sheet 3.Cal.Amo.LT
A1: TABLEAU D'AMORTISSEMENT EMPRUNT A COURT TERME
A3: Année 1
A4: Emprunt | B4: ='1.Var.Fin'!B5 -> 76500 | E4: Montant (FCFA)
A5: Taux Annuel | B5: ='1.Var.Fin'!B7 -> 0.09
A6: TOB | B6: ='1.Var.Fin'!B15 -> 0.1
A7: DUREE | B7: =ROUNDUP('1.Var.Fin'!B8/12,0) -> 3 | C7: ANS
A8: Année | B8: CAPITAL RESTANT DU | C8: INTERET | D8: TOB | E8: Amortissement | F8: Annuité
A9: N | B9: =B4 -> 76500 | C9: =B9*$B$5 -> 6885 | D9: =B9*$B$6 -> 7650 | E9: =F9-C9 -> 23336.689 | F9: =IF(B9>=1,IFERROR($B$4*$B$5/((1-(1+$B$5)^(-$B$7))),0),0) -> 30221.689
A10: N+1 | B10: =B9-E9 -> 53163.311 | C10: =B10*$B$5 -> 4784.698 | D10: =B10*$B$6 -> 5316.3311 | E10: =F10-C10 -> 25436.991 | F10: =IF(B10>=1,IFERROR($B$4*$B$5/((1-(1+$B$5)^(-$B$7))),0),0) -> 30221.689
A11: N+2 | B11: =B10-E10 -> 27726.32 | C11: =B11*$B$5 -> 2495.3688 | D11: =B11*$B$6 -> 2772.632 | E11: =F11-C11 -> 27726.32 | F11: =IF(B11>=1,IFERROR($B$4*$B$5/((1-(1+$B$5)^(-$B$7))),0),0) -> 30221.689
A12: N+3 | B12: =B11-E11 -> 3.2741809e-11 | C12: =B12*$B$5 -> 2.9467628e-12 | D12: =B12*$B$6 -> 3.2741809e-12 | E12: =F12-C12 -> -2.9467628e-12 | F12: =IF(B12>=1,IFERROR($B$4*$B$5/((1-(1+$B$5)^(-$B$7))),0),0) -> 0
A13: N+4 | B13: =B12-E12 -> 3.5688572e-11 | C13: =B13*$B$5 -> 3.2119715e-12 | D13: =B13*$B$6 -> 3.5688572e-12 | E13: =F13-C13 -> -3.2119715e-12 | F13: =IF(B13>=1,IFERROR($B$4*$B$5/((1-(1+$B$5)^(-$B$7))),0),0) -> 0
A14: Année 2
A15: Emprunt | B15: ='1.Var.Fin'!C5 -> 3698500.9 | E15: Montant (FCFA)
A16: Taux Annuel | B16: ='1.Var.Fin'!C7 -> 0.11
A17: TOB | B17: ='1.Var.Fin'!C15 -> 0.1
A18: DUREE | B18: =ROUNDUP('1.Var.Fin'!C8/12,0) -> 3 | C18: ANS
A19: Année | B19: CAPITAL RESTANT DU | C19: INTERET | D19: TOB | E19: Amortissement | F19: Annuité
A20: N+1 | B20: =H15 -> 0 | C20: =B20*$B$5 -> 0 | D20: =B20*$B$6 -> 0 | E20: =F20-C20 -> 0 | F20: =IF(B20>=1,IFERROR($B$4*$B$5/((1-(1+$B$5)^(-$B$7))),0),0) -> 0
A21: N+2 | B21: =B20-E20 -> 0 | C21: =B21*$B$5 -> 0 | D21: =B21*$B$6 -> 0 | E21: =F21-C21 -> 0 | F21: =IF(B21>=1,IFERROR($B$4*$B$5/((1-(1+$B$5)^(-$B$7))),0),0) -> 0
A22: N+3 | B22: =B21-E21 -> 0 | C22: =B22*$B$5 -> 0 | D22: =B22*$B$6 -> 0 | E22: =F22-C22 -> 0 | F22: =IF(B22>=1,IFERROR($B$4*$B$5/((1-(1+$B$5)^(-$B$7))),0),0) -> 0
A23: N+4 | B23: =B22-E22 -> 0 | C23: =B23*$B$5 -> 0 | D23: =B23*$B$6 -> 0 | E23: =F23-C23 -> 0 | F23: =IF(B23>=1,IFERROR($B$4*$B$5/((1-(1+$B$5)^(-$B$7))),0),0) -> 0
A24: N+5 | B24: =B23-E23 -> 0 | C24: =B24*$B$5 -> 0 | D24: =B24*$B$6 -> 0 | E24: =F24-C24 -> 0 | F24: =IF(B24>=1,IFERROR($B$4*$B$5/((1-(1+$B$5)^(-$B$7))),0),0) -> 0
A25: Année 3
A26: Emprunt | B26: ='1.Var.Fin'!D5 -> 0 | E26: Montant (FCFA)
A27: Taux Annuel | B27: ='1.Var.Fin'!D7 -> 0.1
A28: TOB | B28: ='1.Var.Fin'!D15 -> 0.1
A29: DUREE | B29: =ROUNDUP('1.Var.Fin'!D8/12,0) -> 3 | C29: ANS
A30: Année | B30: CAPITAL RESTANT DU | C30: INTERET | D30: TOB | E30: Amortissement | F30: Annuité
A31: N+2 | B31: =H26 -> 0 | C31: =B31*$B$5 -> 0 | D31: =B31*$B$6 -> 0 | E31: =F31-C31 -> 0 | F31: =IF(B31>=1,IFERROR($B$4*$B$5/((1-(1+$B$5)^(-$B$7))),0),0) -> 0
A32: N+3 | B32: =B31-E31 -> 0 | C32: =B32*$B$5 -> 0 | D32: =B32*$B$6 -> 0 | E32: =F32-C32 -> 0 | F32: =IF(B32>=1,IFERROR($B$4*$B$5/((1-(1+$B$5)^(-$B$7))),0),0) -> 0
A33: N+4 | B33: =B32-E32 -> 0 | C33: =B33*$B$5 -> 0 | D33: =B33*$B$6 -> 0 | E33: =F33-C33 -> 0 | F33: =IF(B33>=1,IFERROR($B$4*$B$5/((1-(1+$B$5)^(-$B$7))),0),0) -> 0
A34: N+5 | B34: =B33-E33 -> 0 | C34: =B34*$B$5 -> 0 | D34: =B34*$B$6 -> 0 | E34: =F34-C34 -> 0 | F34: =IF(B34>=1,IFERROR($B$4*$B$5/((1-(1+$B$5)^(-$B$7))),0),0) -> 0
A35: N+6 | B35: =B34-E34 -> 0 | C35: =B35*$B$5 -> 0 | D35: =B35*$B$6 -> 0 | E35: =F35-C35 -> 0 | F35: =IF(B35>=1,IFERROR($B$4*$B$5/((1-(1+$B$5)^(-$B$7))),0),0) -> 0

Sheet 4.Cal.Amo.AI
A1: TABLEAU D'AMORTISSEMENT APPORT INITIAL
A3: Année 1
A4: Emprunt | B4: ='1.Var.Fin'!B17 -> 0 | E4: Montant (FCFA)
A5: Taux Annuel | B5: ='1.Var.Fin'!B19 -> 0
A6: TOB | B6: ='1.Var.Fin'!B21 -> 0.1
A7: DUREE | B7: =ROUNDUP('1.Var.Fin'!B8/12,0) -> 3 | C7: ANS
A8: Année | B8: CAPITAL RESTANT DU | C8: INTERET | D8: TOB | E8: Amortissement | F8: Annuité
A9: N | B9: =B4 -> 0 | C9: =B9*$B$5 -> 0 | D9: =B9*$B$6 -> 0 | E9: =F9-C9 -> 0 | F9: =IF(B9>=1,IFERROR($B$4*$B$5/((1-(1+$B$5)^(-$B$7))),0),0) -> 0
A10: N+1 | B10: =B9-E9 -> 0 | C10: =B10*$B$5 -> 0 | D10: =B10*$B$6 -> 0 | E10: =F10-C10 -> 0 | F10: =IF(B10>=1,IFERROR($B$4*$B$5/((1-(1+$B$5)^(-$B$7))),0),0) -> 0
A11: N+2 | B11: =B10-E10 -> 0 | C11: =B11*$B$5 -> 0 | D11: =B11*$B$6 -> 0 | E11: =F11-C11 -> 0 | F11: =IF(B11>=1,IFERROR($B$4*$B$5/((1-(1+$B$5)^(-$B$7))),0),0) -> 0
A12: N+3 | B12: =B11-E11 -> 0 | C12: =B12*$B$5 -> 0 | D12: =B12*$B$6 -> 0 | E12: =F12-C12 -> 0 | F12: =IF(B12>=1,IFERROR($B$4*$B$5/((1-(1+$B$5)^(-$B$7))),0),0) -> 0
A13: N+4 | B13: =B12-E12 -> 0 | C13: =B13*$B$5 -> 0 | D13: =B13*$B$6 -> 0 | E13: =F13-C13 -> 0 | F13: =IF(B13>=1,IFERROR($B$4*$B$5/((1-(1+$B$5)^(-$B$7))),0),0) -> 0
A14: Année 2
A15: Emprunt | B15: ='1.Var.Fin'!C17 -> 0 | E15: Montant (FCFA)
A16: Taux Annuel | B16: ='1.Var.Fin'!C19 -> 0
A17: TOB | B17: ='1.Var.Fin'!C21 -> 0.1
A18: DUREE | B18: =ROUNDUP('1.Var.Fin'!C8/12,0) -> 3 | C18: ANS
A19: Année | B19: CAPITAL RESTANT DU | C19: INTERET | D19: TOB | E19: Amortissement | F19: Annuité
A20: N | B20: =H15 -> 0 | C20: =B20*$B$5 -> 0 | D20: =B20*$B$6 -> 0 | E20: =F20-C20 -> 0 | F20: =IF(B20>=1,IFERROR($B$4*$B$5/((1-(1+$B$5)^(-$B$7))),0),0) -> 0
A21: N+1 | B21: =B20-E20 -> 0 | C21: =B21*$B$5 -> 0 | D21: =B21*$B$6 -> 0 | E21: =F21-C21 -> 0 | F21: =IF(B21>=1,IFERROR($B$4*$B$5/((1-(1+$B$5)^(-$B$7))),0),0) -> 0
A22: N+2 | B22: =B21-E21 -> 0 | C22: =B22*$B$5 -> 0 | D22: =B22*$B$6 -> 0 | E22: =F22-C22 -> 0 | F22: =IF(B22>=1,IFERROR($B$4*$B$5/((1-(1+$B$5)^(-$B$7))),0),0) -> 0
A23: N+3 | B23: =B22-E22 -> 0 | C23: =B23*$B$5 -> 0 | D23: =B23*$B$6 -> 0 | E23: =F23-C23 -> 0 | F23: =IF(B23>=1,IFERROR($B$4*$B$5/((1-(1+$B$5)^(-$B$7))),0),0) -> 0
A24: N+4 | B24: =B23-E23 -> 0 | C24: =B24*$B$5 -> 0 | D24: =B24*$B$6 -> 0 | E24: =F24-C24 -> 0 | F24: =IF(B24>=1,IFERROR($B$4*$B$5/((1-(1+$B$5)^(-$B$7))),0),0) -> 0
A25: Année 3
A26: Emprunt | B26: ='1.Var.Fin'!D17 -> 0 | E26: Montant (FCFA)
A27: Taux Annuel | B27: ='1.Var.Fin'!D19 -> 0
A28: TOB | B28: ='1.Var.Fin'!D21 -> 0.1
A29: DUREE | B29: =ROUNDUP('1.Var.Fin'!D8/12,0) -> 3 | C29: ANS
A30: Année | B30: CAPITAL RESTANT DU | C30: INTERET | D30: TOB | E30: Amortissement | F30: Annuité
A31: N | B31: =H26 -> 0 | C31: =B31*$B$5 -> 0 | D31: =B31*$B$6 -> 0 | E31: =F31-C31 -> 0 | F31: =IF(B31>=1,IFERROR($B$4*$B$5/((1-(1+$B$5)^(-$B$7))),0),0) -> 0
A32: N+1 | B32: =B31-E31 -> 0 | C32: =B32*$B$5 -> 0 | D32: =B32*$B$6 -> 0 | E32: =F32-C32 -> 0 | F32: =IF(B32>=1,IFERROR($B$4*$B$5/((1-(1+$B$5)^(-$B$7))),0),0) -> 0
A33: N+2 | B33: =B32-E32 -> 0 | C33: =B33*$B$5 -> 0 | D33: =B33*$B$6 -> 0 | E33: =F33-C33 -> 0 | F33: =IF(B33>=1,IFERROR($B$4*$B$5/((1-(1+$B$5)^(-$B$7))),0),0) -> 0
A34: N+3 | B34: =B33-E33 -> 0 | C34: =B34*$B$5 -> 0 | D34: =B34*$B$6 -> 0 | E34: =F34-C34 -> 0 | F34: =IF(B34>=1,IFERROR($B$4*$B$5/((1-(1+$B$5)^(-$B$7))),0),0) -> 0
A35: N+4 | B35: =B34-E34 -> 0 | C35: =B35*$B$5 -> 0 | D35: =B35*$B$6 -> 0 | E35: =F35-C35 -> 0 | F35: =IF(B35>=1,IFERROR($B$4*$B$5/((1-(1+$B$5)^(-$B$7))),0),0) -> 0

Sheet 5.Inv
A1: LISTE DES INVESTISSEMENTS
B3: Type d'immobilisation | C3: Dénomination | D3: CODE FINANCEMENT | E3: Nb | F3: Montant
A4: 1. | B4: Immobilisations corporelles bâtiment | C4: Aménagement et batiments | D4: {var_14} | E4: {var_31} | F4: {var_48}
C5: Aménagement entrepôt | D5: {var_15} | E5: {var_32} | F5: {var_49}
A6: 2. | B6: Immobilisation corporelle véhicules | C6: Véhicules de liaison | D6: {var_16} | E6: {var_33} | F6: {var_50}
C7: Véhicules de bureau | D7: {var_17} | E7: {var_34} | F7: {var_51}
C8: Véhicule administratif | D8: {var_18} | E8: {var_35} | F8: {var_52}
A9: 3. | B9: Autres immobilisations corporelles matériel de travail | C9: Bureau (Fauteuil + table) | D9: {var_19} | E9: {var_36} | F9: {var_53}
C10: Mobilier et matériel de bureau | D10: {var_20} | E10: {var_37} | F10: {var_54}
C11: Bureau (Fauteuil + table) | D11: {var_21} | E11: {var_38} | F11: {var_55}
C12: Ordinateur PRO | D12: {var_22} | E12: {var_39} | F12: {var_56}
C13: Serveur | D13: {var_23} | E13: {var_40} | F13: {var_57}
C14: CANON EOS 80 D + objectif 18-135mm IS USM | D14: {var_24} | E14: {var_41} | F14: {var_58}
C15: Boîtier Canon EOS 5D Mark IV | D15: {var_25} | E15: {var_42} | F15: {var_59}
C16: Photocopieuse + Imprimante | D16: {var_26} | E16: {var_43} | F16: {var_60}
A17: 4. | B17: Immobilisation incorporelles | C17: Caution et avance loyer | D17: {var_27} | E17: {var_44} | F17: {var_61}
C18: Branchement Téléphone et internet | D18: {var_28} | E18: {var_45} | F18: {var_62}
C19: Branchement CIE et SODECI | D19: {var_29} | E19: {var_46} | F19: {var_63}
C20: Bail foncier | D20: {var_30} | E20: {var_47} | F20: {var_64}

Sheet 6.Var.Inv
A1: FACTEURS DE VARIATION INVESTISSEMENT
B3: Type d'immobilisation | C3: Dénomination | D3: CODE FINANCEMENT | E3: 1 | F3: 2 | G3: 3 | H3: 4 | I3: 5 | J3: 6 | K3: 7 | L3: 8 | M3: 9 | N3: 10 | O3: 11 | P3: 12 | Q3: N | R3: N+1 | S3: N+2
A4: ='5.Inv'!A4 -> 1. | B4: ='5.Inv'!B4 -> Immobilisations corporelles bâtiment | C4: ='5.Inv'!C4 -> Aménagement et batiments | D4: ='5.Inv'!D4 -> {var_14} | E4: 1 | Q4: =SUM(E4:P4) -> 1
A5: ='5.Inv'!A5 -> 0 | B5: ='5.Inv'!B5 -> 0 | C5: ='5.Inv'!C5 -> Aménagement entrepôt | D5: ='5.Inv'!D5 -> {var_15} | E5: 1 | Q5: =SUM(E5:P5) -> 1
A6: ='5.Inv'!A6 -> 2. | B6: ='5.Inv'!B6 -> Immobilisation corporelle véhicules | C6: ='5.Inv'!C6 -> Véhicules de liaison | D6: ='5.Inv'!D6 -> {var_16} | E6: 1 | Q6: =SUM(E6:P6) -> 1
A7: ='5.Inv'!A7 -> 0 | B7: ='5.Inv'!B7 -> 0 | C7: ='5.Inv'!C7 -> Véhicules de bureau | D7: ='5.Inv'!D7 -> {var_17} | E7: 1 | Q7: =SUM(E7:P7) -> 1
A8: ='5.Inv'!A8 -> 0 | B8: ='5.Inv'!B8 -> 0 | C8: ='5.Inv'!C8 -> Véhicule administratif | D8: ='5.Inv'!D8 -> {var_18} | E8: 1 | Q8: =SUM(E8:P8) -> 1
A9: ='5.Inv'!A9 -> 3. | B9: ='5.Inv'!B9 -> Autres immobilisations corporelles matériel de travail | C9: ='5.Inv'!C9 -> Bureau (Fauteuil + table) | D9: ='5.Inv'!D9 -> {var_19} | E9: 1 | Q9: =SUM(E9:P9) -> 1
A10: ='5.Inv'!A10 -> 0 | B10: ='5.Inv'!B10 -> 0 | C10: ='5.Inv'!C10 -> Mobilier et matériel de bureau | D10: ='5.Inv'!D10 -> {var_20} | E10: 1 | Q10: =SUM(E10:P10) -> 1
A11: ='5.Inv'!A11 -> 0 | B11: ='5.Inv'!B11 -> 0 | C11: ='5.Inv'!C11 -> Bureau (Fauteuil + table) | D11: ='5.Inv'!D11 -> {var_21} | E11: 1 | Q11: =SUM(E11:P11) -> 1
A12: ='5.Inv'!A12 -> 0 | B12: ='5.Inv'!B12 -> 0 | C12: ='5.Inv'!C12 -> Ordinateur PRO | D12: ='5.Inv'!D12 -> {var_22} | E12: 1 | Q12: =SUM(E12:P12) -> 1
A13: ='5.Inv'!A13 -> 0 | B13: ='5.Inv'!B13 -> 0 | C13: ='5.Inv'!C13 -> Serveur | D13: ='5.Inv'!D13 -> {var_23} | E13: 1 | Q13: =SUM(E13:P13) -> 1
A14: ='5.Inv'!A14 -> 0 | B14: ='5.Inv'!B14 -> 0 | C14: ='5.Inv'!C14 -> CANON EOS 80 D + objectif 18-135mm IS USM | D14: ='5.Inv'!D14 -> {var_24} | E14: 1 | Q14: =SUM(E14:P14) -> 1
C15: ='5.Inv'!C15 -> Boîtier Canon EOS 5D Mark IV | D15: ='5.Inv'!D15 -> {var_25} | E15: 1
A16: ='5.Inv'!A16 -> 0 | B16: ='5.Inv'!B16 -> 0 | C16: ='5.Inv'!C16 -> Photocopieuse + Imprimante | D16: ='5.Inv'!D16 -> {var_26} | E16: 1 | Q16: =SUM(E16:P16) -> 1
A17: ='5.Inv'!A17 -> 4. | B17: ='5.Inv'!B17 -> Immobilisation incorporelles | C17: ='5.Inv'!C17 -> Caution et avance loyer | D17: ='5.Inv'!D17 -> {var_27} | E17: 1 | Q17: =SUM(E17:P17) -> 1
A18: ='5.Inv'!A18 -> 0 | B18: ='5.Inv'!B18 -> 0 | C18: ='5.Inv'!C18 -> Branchement Téléphone et internet | D18: ='5.Inv'!D18 -> {var_28} | E18: 1 | Q18: =SUM(E18:P18) -> 1
A19: ='5.Inv'!A19 -> 0 | B19: ='5.Inv'!B19 -> 0 | C19: ='5.Inv'!C19 -> Branchement CIE et SODECI | D19: ='5.Inv'!D19 -> {var_29} | Q19: =SUM(E19:P19) -> 0
A20: ='5.Inv'!A20 -> 0 | B20: ='5.Inv'!B20 -> 0 | C20: ='5.Inv'!C20 -> Bail foncier | D20: ='5.Inv'!D20 -> {var_30} | Q20: =SUM(E20:P20) -> 0
B21: Total | E21: =AVERAGE(E4:E20) -> 1 | F21: =AVERAGE(F4:F20) -> #DIV/0! | G21: =AVERAGE(G4:G20) -> #DIV/0! | H21: =AVERAGE(H4:H20) -> #DIV/0! | I21: =AVERAGE(I4:I20) -> #DIV/0! | J21: =AVERAGE(J4:J20) -> #DIV/0! | K21: =AVERAGE(K4:K20) -> #DIV/0! | L21: =AVERAGE(L4:L20) -> #DIV/0! | ... S21: =AVERAGE(S4:S20) -> #DIV/0!

Sheet 7.Bud.Inv.
A1: INVESTISSEMENTS
B3: Type d'immobilisation | C3: Immobilisation | D3: CODE FINANCEMENT | E3: 1 | F3: 2 | G3: 3 | H3: 4 | I3: 5 | J3: 6 | K3: 7 | L3: 8 | M3: 9 | N3: 10 | O3: 11 | P3: 12 | Q3: N | R3: N+1 | S3: N+2
A4: ='5.Inv'!A4 -> 1. | B4: ='5.Inv'!B4 -> Immobilisations corporelles bâtiment | C4: ='5.Inv'!C4 -> Aménagement et batiments | D4: ='5.Inv'!D4 -> {var_14} | E4: ='5.Inv'!$E4*'5.Inv'!$F4*'6.Var.Inv'!E4 -> #VALUE! | F4: ='5.Inv'!$E4*'5.Inv'!$F4*'6.Var.Inv'!F4 -> #VALUE! | G4: ='5.Inv'!$E4*'5.Inv'!$F4*'6.Var.Inv'!G4 -> #VALUE! | H4: ='5.Inv'!$E4*'5.Inv'!$F4*'6.Var.Inv'!H4 -> #VALUE! | I4: ='5.Inv'!$E4*'5.Inv'!$F4*'6.Var.Inv'!I4 -> #VALUE! | J4: ='5.Inv'!$E4*'5.Inv'!$F4*'6.Var.Inv'!J4 -> #VALUE! | K4: ='5.Inv'!$E4*'5.Inv'!$F4*'6.Var.Inv'!K4 -> #VALUE! | L4: ='5.Inv'!$E4*'5.Inv'!$F4*'6.Var.Inv'!L4 -> #VALUE! | ... P4: ='5.Inv'!$E4*'5.Inv'!$F4*'6.Var.Inv'!P4 -> #VALUE! | Q4: =SUM(E4:P4) -> #VALUE! | R4: ='5.Inv'!$E4*'5.Inv'!$F4*'6.Var.Inv'!R4 -> #VALUE! | S4: ='5.Inv'!$E4*'5.Inv'!$F4*'6.Var.Inv'!S4 -> #VALUE!
A6: ='5.Inv'!A5 -> 0 | B6: ='5.Inv'!B5 -> 0 | C6: ='5.Inv'!C5 -> Aménagement entrepôt | D6: ='5.Inv'!D5 -> {var_15} | E6: ='5.Inv'!$E5*'5.Inv'!$F5*'6.Var.Inv'!E5 -> #VALUE! | F6: ='5.Inv'!$E5*'5.Inv'!$F5*'6.Var.Inv'!F5 -> #VALUE! | G6: ='5.Inv'!$E5*'5.Inv'!$F5*'6.Var.Inv'!G5 -> #VALUE! | H6: ='5.Inv'!$E5*'5.Inv'!$F5*'6.Var.Inv'!H5 -> #VALUE! | I6: ='5.Inv'!$E5*'5.Inv'!$F5*'6.Var.Inv'!I5 -> #VALUE! | J6: ='5.Inv'!$E5*'5.Inv'!$F5*'6.Var.Inv'!J5 -> #VALUE! | K6: ='5.Inv'!$E5*'5.Inv'!$F5*'6.Var.Inv'!K5 -> #VALUE! | L6: ='5.Inv'!$E5*'5.Inv'!$F5*'6.Var.Inv'!L5 -> #VALUE! | ... P6: ='5.Inv'!$E5*'5.Inv'!$F5*'6.Var.Inv'!P5 -> #VALUE! | Q6: =SUM(E6:P6) -> #VALUE! | R6: ='5.Inv'!$E5*'5.Inv'!$F5*'6.Var.Inv'!R5 -> #VALUE! | S6: ='5.Inv'!$E5*'5.Inv'!$F5*'6.Var.Inv'!S5 -> #VALUE!
A7: ='5.Inv'!A6 -> 2. | B7: ='5.Inv'!B6 -> Immobilisation corporelle véhicules | C7: ='5.Inv'!C6 -> Véhicules de liaison | D7: ='5.Inv'!D6 -> {var_16} | E7: ='5.Inv'!$E6*'5.Inv'!$F6*'6.Var.Inv'!E6 -> #VALUE! | F7: ='5.Inv'!$E6*'5.Inv'!$F6*'6.Var.Inv'!F6 -> #VALUE! | G7: ='5.Inv'!$E6*'5.Inv'!$F6*'6.Var.Inv'!G6 -> #VALUE! | H7: ='5.Inv'!$E6*'5.Inv'!$F6*'6.Var.Inv'!H6 -> #VALUE! | I7: ='5.Inv'!$E6*'5.Inv'!$F6*'6.Var.Inv'!I6 -> #VALUE! | J7: ='5.Inv'!$E6*'5.Inv'!$F6*'6.Var.Inv'!J6 -> #VALUE! | K7: ='5.Inv'!$E6*'5.Inv'!$F6*'6.Var.Inv'!K6 -> #VALUE! | L7: ='5.Inv'!$E6*'5.Inv'!$F6*'6.Var.Inv'!L6 -> #VALUE! | ... P7: ='5.Inv'!$E6*'5.Inv'!$F6*'6.Var.Inv'!P6 -> #VALUE! | Q7: =SUM(E7:P7) -> #VALUE! | R7: ='5.Inv'!$E6*'5.Inv'!$F6*'6.Var.Inv'!R6 -> #VALUE! | S7: ='5.Inv'!$E6*'5.Inv'!$F6*'6.Var.Inv'!S6 -> #VALUE!
A8: ='5.Inv'!A7 -> 0 | B8: ='5.Inv'!B7 -> 0 | C8: ='5.Inv'!C7 -> Véhicules de bureau | D8: ='5.Inv'!D7 -> {var_17} | E8: ='5.Inv'!$E7*'5.Inv'!$F7*'6.Var.Inv'!E7 -> #VALUE! | F8: ='5.Inv'!$E7*'5.Inv'!$F7*'6.Var.Inv'!F7 -> #VALUE! | G8: ='5.Inv'!$E7*'5.Inv'!$F7*'6.Var.Inv'!G7 -> #VALUE! | H8: ='5.Inv'!$E7*'5.Inv'!$F7*'6.Var.Inv'!H7 -> #VALUE! | I8: ='5.Inv'!$E7*'5.Inv'!$F7*'6.Var.Inv'!I7 -> #VALUE! | J8: ='5.Inv'!$E7*'5.Inv'!$F7*'6.Var.Inv'!J7 -> #VALUE! | K8: ='5.Inv'!$E7*'5.Inv'!$F7*'6.Var.Inv'!K7 -> #VALUE! | L8: ='5.Inv'!$E7*'5.Inv'!$F7*'6.Var.Inv'!L7 -> #VALUE! | ... P8: ='5.Inv'!$E7*'5.Inv'!$F7*'6.Var.Inv'!P7 -> #VALUE! | Q8: =SUM(E8:P8) -> #VALUE! | R8: ='5.Inv'!$E7*'5.Inv'!$F7*'6.Var.Inv'!R7 -> #VALUE! | S8: ='5.Inv'!$E7*'5.Inv'!$F7*'6.Var.Inv'!S7 -> #VALUE!
A9: ='5.Inv'!A8 -> 0 | B9: ='5.Inv'!B8 -> 0 | C9: ='5.Inv'!C8 -> Véhicule administratif | D9: ='5.Inv'!D8 -> {var_18} | E9: ='5.Inv'!$E8*'5.Inv'!$F8*'6.Var.Inv'!E8 -> #VALUE! | F9: ='5.Inv'!$E8*'5.Inv'!$F8*'6.Var.Inv'!F8 -> #VALUE! | G9: ='5.Inv'!$E8*'5.Inv'!$F8*'6.Var.Inv'!G8 -> #VALUE! | H9: ='5.Inv'!$E8*'5.Inv'!$F8*'6.Var.Inv'!H8 -> #VALUE! | I9: ='5.Inv'!$E8*'5.Inv'!$F8*'6.Var.Inv'!I8 -> #VALUE! | J9: ='5.Inv'!$E8*'5.Inv'!$F8*'6.Var.Inv'!J8 -> #VALUE! | K9: ='5.Inv'!$E8*'5.Inv'!$F8*'6.Var.Inv'!K8 -> #VALUE! | L9: ='5.Inv'!$E8*'5.Inv'!$F8*'6.Var.Inv'!L8 -> #VALUE! | ... P9: ='5.Inv'!$E8*'5.Inv'!$F8*'6.Var.Inv'!P8 -> #VALUE! | Q9: =SUM(E9:P9) -> #VALUE! | R9: ='5.Inv'!$E8*'5.Inv'!$F8*'6.Var.Inv'!R8 -> #VALUE! | S9: ='5.Inv'!$E8*'5.Inv'!$F8*'6.Var.Inv'!S8 -> #VALUE!
A10: ='5.Inv'!A9 -> 3. | B10: ='5.Inv'!B9 -> Autres immobilisations corporelles matériel de travail | C10: ='5.Inv'!C9 -> Bureau (Fauteuil + table) | D10: ='5.Inv'!D9 -> {var_19} | E10: ='5.Inv'!$E9*'5.Inv'!$F9*'6.Var.Inv'!E9 -> #VALUE! | F10: ='5.Inv'!$E9*'5.Inv'!$F9*'6.Var.Inv'!F9 -> #VALUE! | G10: ='5.Inv'!$E9*'5.Inv'!$F9*'6.Var.Inv'!G9 -> #VALUE! | H10: ='5.Inv'!$E9*'5.Inv'!$F9*'6.Var.Inv'!H9 -> #VALUE! | I10: ='5.Inv'!$E9*'5.Inv'!$F9*'6.Var.Inv'!I9 -> #VALUE! | J10: ='5.Inv'!$E9*'5.Inv'!$F9*'6.Var.Inv'!J9 -> #VALUE! | K10: ='5.Inv'!$E9*'5.Inv'!$F9*'6.Var.Inv'!K9 -> #VALUE! | L10: ='5.Inv'!$E9*'5.Inv'!$F9*'6.Var.Inv'!L9 -> #VALUE! | ... P10: ='5.Inv'!$E9*'5.Inv'!$F9*'6.Var.Inv'!P9 -> #VALUE! | Q10: =SUM(E10:P10) -> #VALUE! | R10: ='5.Inv'!$E9*'5.Inv'!$F9*'6.Var.Inv'!R9 -> #VALUE! | S10: ='5.Inv'!$E9*'5.Inv'!$F9*'6.Var.Inv'!S9 -> #VALUE!
A11: ='5.Inv'!A10 -> 0 | B11: ='5.Inv'!B10 -> 0 | C11: ='5.Inv'!C10 -> Mobilier et matériel de bureau | D11: ='5.Inv'!D10 -> {var_20} | E11: ='5.Inv'!$E10*'5.Inv'!$F10*'6.Var.Inv'!E10 -> #VALUE! | F11: ='5.Inv'!$E10*'5.Inv'!$F10*'6.Var.Inv'!F10 -> #VALUE! | G11: ='5.Inv'!$E10*'5.Inv'!$F10*'6.Var.Inv'!G10 -> #VALUE! | H11: ='5.Inv'!$E10*'5.Inv'!$F10*'6.Var.Inv'!H10 -> #VALUE! | I11: ='5.Inv'!$E10*'5.Inv'!$F10*'6.Var.Inv'!I10 -> #VALUE! | J11: ='5.Inv'!$E10*'5.Inv'!$F10*'6.Var.Inv'!J10 -> #VALUE! | K11: ='5.Inv'!$E10*'5.Inv'!$F10*'6.Var.Inv'!K10 -> #VALUE! | L11: ='5.Inv'!$E10*'5.Inv'!$F10*'6.Var.Inv'!L10 -> #VALUE! | ... P11: ='5.Inv'!$E10*'5.Inv'!$F10*'6.Var.Inv'!P10 -> #VALUE! | Q11: =SUM(E11:P11) -> #VALUE! | R11: ='5.Inv'!$E10*'5.Inv'!$F10*'6.Var.Inv'!R10 -> #VALUE! | S11: ='5.Inv'!$E10*'5.Inv'!$F10*'6.Var.Inv'!S10 -> #VALUE!
A12: ='5.Inv'!A11 -> 0 | B12: ='5.Inv'!B11 -> 0 | C12: ='5.Inv'!C11 -> Bureau (Fauteuil + table) | D12: ='5.Inv'!D11 -> {var_21} | E12: ='5.Inv'!$E11*'5.Inv'!$F11*'6.Var.Inv'!E11 -> #VALUE! | F12: ='5.Inv'!$E11*'5.Inv'!$F11*'6.Var.Inv'!F11 -> #VALUE! | G12: ='5.Inv'!$E11*'5.Inv'!$F11*'6.Var.Inv'!G11 -> #VALUE! | H12: ='5.Inv'!$E11*'5.Inv'!$F11*'6.Var.Inv'!H11 -> #VALUE! | I12: ='5.Inv'!$E11*'5.Inv'!$F11*'6.Var.Inv'!I11 -> #VALUE! | J12: ='5.Inv'!$E11*'5.Inv'!$F11*'6.Var.Inv'!J11 -> #VALUE! | K12: ='5.Inv'!$E11*'5.Inv'!$F11*'6.Var.Inv'!K11 -> #VALUE! | L12: ='5.Inv'!$E11*'5.Inv'!$F11*'6.Var.Inv'!L11 -> #VALUE! | ... P12: ='5.Inv'!$E11*'5.Inv'!$F11*'6.Var.Inv'!P11 -> #VALUE! | Q12: =SUM(E12:P12) -> #VALUE! | R12: ='5.Inv'!$E11*'5.Inv'!$F11*'6.Var.Inv'!R11 -> #VALUE! | S12: ='5.Inv'!$E11*'5.Inv'!$F11*'6.Var.Inv'!S11 -> #VALUE!
A13: ='5.Inv'!A12 -> 0 | B13: ='5.Inv'!B12 -> 0 | C13: ='5.Inv'!C12 -> Ordinateur PRO | D13: ='5.Inv'!D12 -> {var_22} | E13: ='5.Inv'!$E12*'5.Inv'!$F12*'6.Var.Inv'!E12 -> #VALUE! | F13: ='5.Inv'!$E12*'5.Inv'!$F12*'6.Var.Inv'!F12 -> #VALUE! | G13: ='5.Inv'!$E12*'5.Inv'!$F12*'6.Var.Inv'!G12 -> #VALUE! | H13: ='5.Inv'!$E12*'5.Inv'!$F12*'6.Var.Inv'!H12 -> #VALUE! | I13: ='5.Inv'!$E12*'5.Inv'!$F12*'6.Var.Inv'!I12 -> #VALUE! | J13: ='5.Inv'!$E12*'5.Inv'!$F12*'6.Var.Inv'!J12 -> #VALUE! | K13: ='5.Inv'!$E12*'5.Inv'!$F12*'6.Var.Inv'!K12 -> #VALUE! | L13: ='5.Inv'!$E12*'5.Inv'!$F12*'6.Var.Inv'!L12 -> #VALUE! | ... P13: ='5.Inv'!$E12*'5.Inv'!$F12*'6.Var.Inv'!P12 -> #VALUE! | Q13: =SUM(E13:P13) -> #VALUE! | R13: ='5.Inv'!$E12*'5.Inv'!$F12*'6.Var.Inv'!R12 -> #VALUE! | S13: ='5.Inv'!$E12*'5.Inv'!$F12*'6.Var.Inv'!S12 -> #VALUE!
C14: ='5.Inv'!C13 -> Serveur | D14: ='5.Inv'!D13 -> {var_23} | E14: ='5.Inv'!$E13*'5.Inv'!$F13*'6.Var.Inv'!E13 -> #VALUE! | F14: ='5.Inv'!$E13*'5.Inv'!$F13*'6.Var.Inv'!F13 -> #VALUE! | G14: ='5.Inv'!$E13*'5.Inv'!$F13*'6.Var.Inv'!G13 -> #VALUE! | H14: ='5.Inv'!$E13*'5.Inv'!$F13*'6.Var.Inv'!H13 -> #VALUE! | I14: ='5.Inv'!$E13*'5.Inv'!$F13*'6.Var.Inv'!I13 -> #VALUE! | J14: ='5.Inv'!$E13*'5.Inv'!$F13*'6.Var.Inv'!J13 -> #VALUE! | K14: ='5.Inv'!$E13*'5.Inv'!$F13*'6.Var.Inv'!K13 -> #VALUE! | L14: ='5.Inv'!$E13*'5.Inv'!$F13*'6.Var.Inv'!L13 -> #VALUE! | ... P14: ='5.Inv'!$E13*'5.Inv'!$F13*'6.Var.Inv'!P13 -> #VALUE! | Q14: =SUM(E14:P14) -> #VALUE! | R14: ='5.Inv'!$E13*'5.Inv'!$F13*'6.Var.Inv'!R13 -> #VALUE! | S14: ='5.Inv'!$E13*'5.Inv'!$F13*'6.Var.Inv'!S13 -> #VALUE!
A15: ='5.Inv'!A13 -> 0 | B15: ='5.Inv'!B13 -> 0 | C15: ='5.Inv'!C14 -> CANON EOS 80 D + objectif 18-135mm IS USM | D15: ='5.Inv'!D14 -> {var_24} | E15: ='5.Inv'!$E14*'5.Inv'!$F14*'6.Var.Inv'!E14 -> #VALUE! | F15: ='5.Inv'!$E14*'5.Inv'!$F14*'6.Var.Inv'!F14 -> #VALUE! | G15: ='5.Inv'!$E14*'5.Inv'!$F14*'6.Var.Inv'!G14 -> #VALUE! | H15: ='5.Inv'!$E14*'5.Inv'!$F14*'6.Var.Inv'!H14 -> #VALUE! | I15: ='5.Inv'!$E14*'5.Inv'!$F14*'6.Var.Inv'!I14 -> #VALUE! | J15: ='5.Inv'!$E14*'5.Inv'!$F14*'6.Var.Inv'!J14 -> #VALUE! | K15: ='5.Inv'!$E14*'5.Inv'!$F14*'6.Var.Inv'!K14 -> #VALUE! | L15: ='5.Inv'!$E14*'5.Inv'!$F14*'6.Var.Inv'!L14 -> #VALUE! | ... P15: ='5.Inv'!$E14*'5.Inv'!$F14*'6.Var.Inv'!P14 -> #VALUE! | Q15: =SUM(E15:P15) -> #VALUE! | R15: ='5.Inv'!$E14*'5.Inv'!$F14*'6.Var.Inv'!R14 -> #VALUE! | S15: ='5.Inv'!$E14*'5.Inv'!$F14*'6.Var.Inv'!S14 -> #VALUE!
A16: ='5.Inv'!A14 -> 0 | B16: ='5.Inv'!B14 -> 0 | C16: ='5.Inv'!C15 -> Boîtier Canon EOS 5D Mark IV | D16: ='5.Inv'!D15 -> {var_25} | E16: ='5.Inv'!$E15*'5.Inv'!$F15*'6.Var.Inv'!E15 -> #VALUE! | F16: ='5.Inv'!$E15*'5.Inv'!$F15*'6.Var.Inv'!F15 -> #VALUE! | G16: ='5.Inv'!$E15*'5.Inv'!$F15*'6.Var.Inv'!G15 -> #VALUE! | H16: ='5.Inv'!$E15*'5.Inv'!$F15*'6.Var.Inv'!H15 -> #VALUE! | I16: ='5.Inv'!$E15*'5.Inv'!$F15*'6.Var.Inv'!I15 -> #VALUE! | J16: ='5.Inv'!$E15*'5.Inv'!$F15*'6.Var.Inv'!J15 -> #VALUE! | K16: ='5.Inv'!$E15*'5.Inv'!$F15*'6.Var.Inv'!K15 -> #VALUE! | L16: ='5.Inv'!$E15*'5.Inv'!$F15*'6.Var.Inv'!L15 -> #VALUE! | ... P16: ='5.Inv'!$E15*'5.Inv'!$F15*'6.Var.Inv'!P15 -> #VALUE! | Q16: =SUM(E16:P16) -> #VALUE! | R16: ='5.Inv'!$E15*'5.Inv'!$F15*'6.Var.Inv'!R15 -> #VALUE! | S16: ='5.Inv'!$E15*'5.Inv'!$F15*'6.Var.Inv'!S15 -> #VALUE!
A17: ='5.Inv'!A16 -> 0 | B17: ='5.Inv'!B16 -> 0 | C17: ='5.Inv'!C16 -> Photocopieuse + Imprimante | D17: ='5.Inv'!D16 -> {var_26} | E17: ='5.Inv'!$E16*'5.Inv'!$F16*'6.Var.Inv'!E16 -> #VALUE! | F17: ='5.Inv'!$E16*'5.Inv'!$F16*'6.Var.Inv'!F16 -> #VALUE! | G17: ='5.Inv'!$E16*'5.Inv'!$F16*'6.Var.Inv'!G16 -> #VALUE! | H17: ='5.Inv'!$E16*'5.Inv'!$F16*'6.Var.Inv'!H16 -> #VALUE! | I17: ='5.Inv'!$E16*'5.Inv'!$F16*'6.Var.Inv'!I16 -> #VALUE! | J17: ='5.Inv'!$E16*'5.Inv'!$F16*'6.Var.Inv'!J16 -> #VALUE! | K17: ='5.Inv'!$E16*'5.Inv'!$F16*'6.Var.Inv'!K16 -> #VALUE! | L17: ='5.Inv'!$E16*'5.Inv'!$F16*'6.Var.Inv'!L16 -> #VALUE! | ... P17: ='5.Inv'!$E16*'5.Inv'!$F16*'6.Var.Inv'!P16 -> #VALUE! | Q17: =SUM(E17:P17) -> #VALUE! | R17: ='5.Inv'!$E16*'5.Inv'!$F16*'6.Var.Inv'!R16 -> #VALUE! | S17: ='5.Inv'!$E16*'5.Inv'!$F16*'6.Var.Inv'!S16 -> #VALUE!
A18: ='5.Inv'!A17 -> 4. | B18: ='5.Inv'!B17 -> Immobilisation incorporelles | C18: ='5.Inv'!C17 -> Caution et avance loyer | D18: ='5.Inv'!D17 -> {var_27} | E18: ='5.Inv'!$E17*'5.Inv'!$F17*'6.Var.Inv'!E17 -> #VALUE! | F18: ='5.Inv'!$E17*'5.Inv'!$F17*'6.Var.Inv'!F17 -> #VALUE! | G18: ='5.Inv'!$E17*'5.Inv'!$F17*'6.Var.Inv'!G17 -> #VALUE! | H18: ='5.Inv'!$E17*'5.Inv'!$F17*'6.Var.Inv'!H17 -> #VALUE! | I18: ='5.Inv'!$E17*'5.Inv'!$F17*'6.Var.Inv'!I17 -> #VALUE! | J18: ='5.Inv'!$E17*'5.Inv'!$F17*'6.Var.Inv'!J17 -> #VALUE! | K18: ='5.Inv'!$E17*'5.Inv'!$F17*'6.Var.Inv'!K17 -> #VALUE! | L18: ='5.Inv'!$E17*'5.Inv'!$F17*'6.Var.Inv'!L17 -> #VALUE! | ... P18: ='5.Inv'!$E17*'5.Inv'!$F17*'6.Var.Inv'!P17 -> #VALUE! | Q18: =SUM(E18:P18) -> #VALUE! | R18: ='5.Inv'!$E17*'5.Inv'!$F17*'6.Var.Inv'!R17 -> #VALUE! | S18: ='5.Inv'!$E17*'5.Inv'!$F17*'6.Var.Inv'!S17 -> #VALUE!
A19: ='5.Inv'!A18 -> 0 | B19: ='5.Inv'!B18 -> 0 | C19: ='5.Inv'!C18 -> Branchement Téléphone et internet | D19: ='5.Inv'!D18 -> {var_28} | E19: ='5.Inv'!$E18*'5.Inv'!$F18*'6.Var.Inv'!E18 -> #VALUE! | F19: ='5.Inv'!$E18*'5.Inv'!$F18*'6.Var.Inv'!F18 -> #VALUE! | G19: ='5.Inv'!$E18*'5.Inv'!$F18*'6.Var.Inv'!G18 -> #VALUE! | H19: ='5.Inv'!$E18*'5.Inv'!$F18*'6.Var.Inv'!H18 -> #VALUE! | I19: ='5.Inv'!$E18*'5.Inv'!$F18*'6.Var.Inv'!I18 -> #VALUE! | J19: ='5.Inv'!$E18*'5.Inv'!$F18*'6.Var.Inv'!J18 -> #VALUE! | K19: ='5.Inv'!$E18*'5.Inv'!$F18*'6.Var.Inv'!K18 -> #VALUE! | L19: ='5.Inv'!$E18*'5.Inv'!$F18*'6.Var.Inv'!L18 -> #VALUE! | ... P19: ='5.Inv'!$E18*'5.Inv'!$F18*'6.Var.Inv'!P18 -> #VALUE! | Q19: =SUM(E19:P19) -> #VALUE! | R19: ='5.Inv'!$E18*'5.Inv'!$F18*'6.Var.Inv'!R18 -> #VALUE! | S19: ='5.Inv'!$E18*'5.Inv'!$F18*'6.Var.Inv'!S18 -> #VALUE!
A20: ='5.Inv'!A19 -> 0 | B20: ='5.Inv'!B19 -> 0 | C20: ='5.Inv'!C19 -> Branchement CIE et SODECI | D20: ='5.Inv'!D19 -> {var_29} | E20: ='5.Inv'!$E19*'5.Inv'!$F19*'6.Var.Inv'!E19 -> #VALUE! | F20: ='5.Inv'!$E19*'5.Inv'!$F19*'6.Var.Inv'!F19 -> #VALUE! | G20: ='5.Inv'!$E19*'5.Inv'!$F19*'6.Var.Inv'!G19 -> #VALUE! | H20: ='5.Inv'!$E19*'5.Inv'!$F19*'6.Var.Inv'!H19 -> #VALUE! | I20: ='5.Inv'!$E19*'5.Inv'!$F19*'6.Var.Inv'!I19 -> #VALUE! | J20: ='5.Inv'!$E19*'5.Inv'!$F19*'6.Var.Inv'!J19 -> #VALUE! | K20: ='5.Inv'!$E19*'5.Inv'!$F19*'6.Var.Inv'!K19 -> #VALUE! | L20: ='5.Inv'!$E19*'5.Inv'!$F19*'6.Var.Inv'!L19 -> #VALUE! | ... P20: ='5.Inv'!$E19*'5.Inv'!$F19*'6.Var.Inv'!P19 -> #VALUE! | Q20: =SUM(E20:P20) -> #VALUE! | R20: ='5.Inv'!$E19*'5.Inv'!$F19*'6.Var.Inv'!R19 -> #VALUE! | S20: ='5.Inv'!$E19*'5.Inv'!$F19*'6.Var.Inv'!S19 -> #VALUE!
A21: ='5.Inv'!A20 -> 0 | B21: ='5.Inv'!B20 -> 0 | C21: ='5.Inv'!C20 -> Bail foncier | D21: ='5.Inv'!D20 -> {var_30} | E21: ='5.Inv'!$E20*'5.Inv'!$F20*'6.Var.Inv'!E20 -> #VALUE! | F21: ='5.Inv'!$E20*'5.Inv'!$F20*'6.Var.Inv'!F20 -> #VALUE! | G21: ='5.Inv'!$E20*'5.Inv'!$F20*'6.Var.Inv'!G20 -> #VALUE! | H21: ='5.Inv'!$E20*'5.Inv'!$F20*'6.Var.Inv'!H20 -> #VALUE! | I21: ='5.Inv'!$E20*'5.Inv'!$F20*'6.Var.Inv'!I20 -> #VALUE! | J21: ='5.Inv'!$E20*'5.Inv'!$F20*'6.Var.Inv'!J20 -> #VALUE! | K21: ='5.Inv'!$E20*'5.Inv'!$F20*'6.Var.Inv'!K20 -> #VALUE! | L21: ='5.Inv'!$E20*'5.Inv'!$F20*'6.Var.Inv'!L20 -> #VALUE! | ... P21: ='5.Inv'!$E20*'5.Inv'!$F20*'6.Var.Inv'!P20 -> #VALUE! | Q21: =SUM(E21:P21) -> #VALUE! | R21: ='5.Inv'!$E20*'5.Inv'!$F20*'6.Var.Inv'!R20 -> #VALUE! | S21: ='5.Inv'!$E20*'5.Inv'!$F20*'6.Var.Inv'!S20 -> #VALUE!
B22: Total | C22: Total | E22: =SUM(E4:E21) -> #VALUE! | F22: =SUM(F4:F21) -> #VALUE! | G22: =SUM(G4:G21) -> #VALUE! | H22: =SUM(H4:H21) -> #VALUE! | I22: =SUM(I4:I21) -> #VALUE! | J22: =SUM(J4:J21) -> #VALUE! | K22: =SUM(K4:K21) -> #VALUE! | L22: =SUM(L4:L21) -> #VALUE! | ... S22: =SUM(S4:S21) -> #VALUE!

Sheet 8.Prod
A1: LISTES DES VENTES
A3: Type de produit | B3: Nom | C3: CODE | D3: Qté | E3: Prix
A4: Ventes de marchandises | B4: CA de Tenue de luxe Homme | C4: VEN1 | D4: =BP_Pres!C11 -> {var_5} | E4: =BP_Pres!D11 -> {var_9}
A5: Ventes de marchandises | B5: CA de Tenue de luxe Femme | C5: VEN1 | D5: =BP_Pres!C12 -> {var_6} | E5: =BP_Pres!D12 -> {var_10}
A6: Ventes de marchandises | B6: CA de Prêt-à-porter homme | C6: VEN1 | D6: =BP_Pres!C13 -> {var_7} | E6: =BP_Pres!D13 -> {var_12}
A7: Ventes de marchandises | B7: CA de Prêt-à-porter femme | C7: VEN1 | D7: =BP_Pres!C14 -> {var_8} | E7: =BP_Pres!D14 -> {var_13}
A8: Ventes de produits fabriqués | C8: VEN2
A9: Vente de services | C9: VEN3
A10: Ventes d'autre produits | C10: VEN4

Sheet 9.Var.Vente1
A1: FACTEURS DE VARIATION VENTES
D2: Ventes mensuelles | P2: Ventes Annuelles
A4: Type de produit | B4: Produit | C4: CODE | D4: 1 | E4: 2 | F4: 3 | G4: 4 | H4: 5 | I4: 6 | J4: 7 | K4: 8 | L4: 9 | M4: 10 | N4: 11 | O4: 12 | P4: N | Q4: N+1 | R4: N+2
A5: ='8.Prod'!A4 -> Ventes de marchandises | B5: ='8.Prod'!B4 -> CA de Tenue de luxe Homme | C5: ='8.Prod'!C4 -> VEN1 | D5: 60 | E5: 60 | F5: 60 | G5: 60 | H5: 60 | I5: 60 | J5: 60 | K5: 60 | L5: 60 | M5: 60 | N5: 60 | O5: 60 | P5: 720 | Q5: 792 | R5: 871.2
A6: ='8.Prod'!A5 -> Ventes de marchandises | B6: ='8.Prod'!B5 -> CA de Tenue de luxe Femme | C6: ='8.Prod'!C5 -> VEN1 | D6: 114 | E6: 114 | F6: 114 | G6: 114 | H6: 114 | I6: 114 | J6: 114 | K6: 114 | L6: 114 | M6: 114 | N6: 114 | O6: 114 | P6: 1368 | Q6: 1504.8 | R6: 1655.28
A7: ='8.Prod'!A6 -> Ventes de marchandises | B7: ='8.Prod'!B6 -> CA de Prêt-à-porter homme | C7: ='8.Prod'!C6 -> VEN1 | D7: 240 | E7: 240 | F7: 240 | G7: 240 | H7: 240 | I7: 240 | J7: 240 | K7: 240 | L7: 240 | M7: 240 | N7: 240 | O7: 240 | P7: 2880 | Q7: 3168 | R7: 3484.8
A8: ='8.Prod'!A7 -> Ventes de marchandises | B8: ='8.Prod'!B7 -> CA de Prêt-à-porter femme | C8: ='8.Prod'!C7 -> VEN1 | D8: 456 | E8: 456 | F8: 456 | G8: 456 | H8: 456 | I8: 456 | J8: 456 | K8: 456 | L8: 456 | M8: 456 | N8: 456 | O8: 456 | P8: 5472 | Q8: 6019.2 | R8: 6621.12
A9: ='8.Prod'!A8 -> Ventes de produits fabriqués | B9: ='8.Prod'!B8 -> 0 | C9: ='8.Prod'!C8 -> VEN2 | Q9: 1.1 | R9: 1.1
A10: ='8.Prod'!A9 -> Vente de services | B10: ='8.Prod'!B9 -> 0 | C10: ='8.Prod'!C9 -> VEN3 | Q10: 1.1 | R10: 1.1
A11: ='8.Prod'!A10 -> Ventes d'autre produits | B11: ='8.Prod'!B10 -> 0 | C11: ='8.Prod'!C10 -> VEN4 | Q11: 1.1 | R11: 1.1
A12: Total | D12: =AVERAGE(D5:D11) -> 217.5 | E12: =AVERAGE(E5:E11) -> 217.5 | F12: =AVERAGE(F5:F11) -> 217.5 | G12: =AVERAGE(G5:G11) -> 217.5 | H12: =AVERAGE(H5:H11) -> 217.5 | I12: =AVERAGE(I5:I11) -> 217.5 | J12: =AVERAGE(J5:J11) -> 217.5 | K12: =AVERAGE(K5:K11) -> 217.5 | ... R12: =AVERAGE(R5:R11) -> 1805.1

Sheet 10.Vente
A1: VENTES
D2: Ventes mensuelles | P2: Ventes Annuelles
A4: Type de produit | B4: Produit | C4: CODE | D4: 1 | E4: 2 | F4: 3 | G4: 4 | H4: 5 | I4: 6 | J4: 7 | K4: 8 | L4: 9 | M4: 10 | N4: 11 | O4: 12 | P4: N | Q4: N+1 | R4: N+2
A5: ='8.Prod'!A4 -> Ventes de marchandises | B5: ='8.Prod'!B4 -> CA de Tenue de luxe Homme | C5: ='8.Prod'!C4 -> VEN1 | D5: ='8.Prod'!$D4*'8.Prod'!$E4*'9.Var.Vente1'!D5 -> #VALUE! | E5: ='8.Prod'!$D4*'8.Prod'!$E4*'9.Var.Vente1'!E5 -> #VALUE! | F5: ='8.Prod'!$D4*'8.Prod'!$E4*'9.Var.Vente1'!F5 -> #VALUE! | G5: ='8.Prod'!$D4*'8.Prod'!$E4*'9.Var.Vente1'!G5 -> #VALUE! | H5: ='8.Prod'!$D4*'8.Prod'!$E4*'9.Var.Vente1'!H5 -> #VALUE! | I5: ='8.Prod'!$D4*'8.Prod'!$E4*'9.Var.Vente1'!I5 -> #VALUE! | J5: ='8.Prod'!$D4*'8.Prod'!$E4*'9.Var.Vente1'!J5 -> #VALUE! | K5: ='8.Prod'!$D4*'8.Prod'!$E4*'9.Var.Vente1'!K5 -> #VALUE! | ... R5: ='8.Prod'!$D4*'8.Prod'!$E4*'9.Var.Vente1'!R5 -> #VALUE!
A6: ='8.Prod'!A5 -> Ventes de marchandises | B6: ='8.Prod'!B5 -> CA de Tenue de luxe Femme | C6: ='8.Prod'!C5 -> VEN1 | D6: ='8.Prod'!$D5*'8.Prod'!$E5*'9.Var.Vente1'!D6 -> #VALUE! | E6: ='8.Prod'!$D5*'8.Prod'!$E5*'9.Var.Vente1'!E6 -> #VALUE! | F6: ='8.Prod'!$D5*'8.Prod'!$E5*'9.Var.Vente1'!F6 -> #VALUE! | G6: ='8.Prod'!$D5*'8.Prod'!$E5*'9.Var.Vente1'!G6 -> #VALUE! | H6: ='8.Prod'!$D5*'8.Prod'!$E5*'9.Var.Vente1'!H6 -> #VALUE! | I6: ='8.Prod'!$D5*'8.Prod'!$E5*'9.Var.Vente1'!I6 -> #VALUE! | J6: ='8.Prod'!$D5*'8.Prod'!$E5*'9.Var.Vente1'!J6 -> #VALUE! | K6: ='8.Prod'!$D5*'8.Prod'!$E5*'9.Var.Vente1'!K6 -> #VALUE! | ... R6: ='8.Prod'!$D5*'8.Prod'!$E5*'9.Var.Vente1'!R6 -> #VALUE!
A7: ='8.Prod'!A6 -> Ventes de marchandises | B7: ='8.Prod'!B6 -> CA de Prêt-à-porter homme | C7: ='8.Prod'!C6 -> VEN1 | D7: ='8.Prod'!$D6*'8.Prod'!$E6*'9.Var.Vente1'!D7 -> #VALUE! | E7: ='8.Prod'!$D6*'8.Prod'!$E6*'9.Var.Vente1'!E7 -> #VALUE! | F7: ='8.Prod'!$D6*'8.Prod'!$E6*'9.Var.Vente1'!F7 -> #VALUE! | G7: ='8.Prod'!$D6*'8.Prod'!$E6*'9.Var.Vente1'!G7 -> #VALUE! | H7: ='8.Prod'!$D6*'8.Prod'!$E6*'9.Var.Vente1'!H7 -> #VALUE! | I7: ='8.Prod'!$D6*'8.Prod'!$E6*'9.Var.Vente1'!I7 -> #VALUE! | J7: ='8.Prod'!$D6*'8.Prod'!$E6*'9.Var.Vente1'!J7 -> #VALUE! | K7: ='8.Prod'!$D6*'8.Prod'!$E6*'9.Var.Vente1'!K7 -> #VALUE! | ... R7: ='8.Prod'!$D6*'8.Prod'!$E6*'9.Var.Vente1'!R7 -> #VALUE!
A8: ='8.Prod'!A7 -> Ventes de marchandises | B8: ='8.Prod'!B7 -> CA de Prêt-à-porter femme | C8: ='8.Prod'!C7 -> VEN1 | D8: ='8.Prod'!$D7*'8.Prod'!$E7*'9.Var.Vente1'!D8 -> #VALUE! | E8: ='8.Prod'!$D7*'8.Prod'!$E7*'9.Var.Vente1'!E8 -> #VALUE! | F8: ='8.Prod'!$D7*'8.Prod'!$E7*'9.Var.Vente1'!F8 -> #VALUE! | G8: ='8.Prod'!$D7*'8.Prod'!$E7*'9.Var.Vente1'!G8 -> #VALUE! | H8: ='8.Prod'!$D7*'8.Prod'!$E7*'9.Var.Vente1'!H8 -> #VALUE! | I8: ='8.Prod'!$D7*'8.Prod'!$E7*'9.Var.Vente1'!I8 -> #VALUE! | J8: ='8.Prod'!$D7*'8.Prod'!$E7*'9.Var.Vente1'!J8 -> #VALUE! | K8: ='8.Prod'!$D7*'8.Prod'!$E7*'9.Var.Vente1'!K8 -> #VALUE! | ... R8: ='8.Prod'!$D7*'8.Prod'!$E7*'9.Var.Vente1'!R8 -> #VALUE!
A9: ='8.Prod'!A8 -> Ventes de produits fabriqués | B9: ='8.Prod'!B8 -> 0 | C9: ='8.Prod'!C8 -> VEN2 | D9: ='8.Prod'!$D8*'8.Prod'!$E8*'9.Var.Vente1'!D9 -> 0 | E9: ='8.Prod'!$D8*'8.Prod'!$E8*'9.Var.Vente1'!E9 -> 0 | F9: ='8.Prod'!$D8*'8.Prod'!$E8*'9.Var.Vente1'!F9 -> 0 | G9: ='8.Prod'!$D8*'8.Prod'!$E8*'9.Var.Vente1'!G9 -> 0 | H9: ='8.Prod'!$D8*'8.Prod'!$E8*'9.Var.Vente1'!H9 -> 0 | I9: ='8.Prod'!$D8*'8.Prod'!$E8*'9.Var.Vente1'!I9 -> 0 | J9: ='8.Prod'!$D8*'8.Prod'!$E8*'9.Var.Vente1'!J9 -> 0 | K9: ='8.Prod'!$D8*'8.Prod'!$E8*'9.Var.Vente1'!K9 -> 0 | ... R9: ='8.Prod'!$D8*'8.Prod'!$E8*'9.Var.Vente1'!R9 -> 0
A10: ='8.Prod'!A9 -> Vente de services | B10: ='8.Prod'!B9 -> 0 | C10: ='8.Prod'!C9 -> VEN3 | D10: ='8.Prod'!$D9*'8.Prod'!$E9*'9.Var.Vente1'!D10 -> 0 | E10: ='8.Prod'!$D9*'8.Prod'!$E9*'9.Var.Vente1'!E10 -> 0 | F10: ='8.Prod'!$D9*'8.Prod'!$E9*'9.Var.Vente1'!F10 -> 0 | G10: ='8.Prod'!$D9*'8.Prod'!$E9*'9.Var.Vente1'!G10 -> 0 | H10: ='8.Prod'!$D9*'8.Prod'!$E9*'9.Var.Vente1'!H10 -> 0 | I10: ='8.Prod'!$D9*'8.Prod'!$E9*'9.Var.Vente1'!I10 -> 0 | J10: ='8.Prod'!$D9*'8.Prod'!$E9*'9.Var.Vente1'!J10 -> 0 | K10: ='8.Prod'!$D9*'8.Prod'!$E9*'9.Var.Vente1'!K10 -> 0 | ... R10: ='8.Prod'!$D9*'8.Prod'!$E9*'9.Var.Vente1'!R10 -> 0
A11: ='8.Prod'!A10 -> Ventes d'autre produits | B11: ='8.Prod'!B10 -> 0 | C11: ='8.Prod'!C10 -> VEN4 | D11: ='8.Prod'!$D10*'8.Prod'!$E10*'9.Var.Vente1'!D11 -> 0 | E11: ='8.Prod'!$D10*'8.Prod'!$E10*'9.Var.Vente1'!E11 -> 0 | F11: ='8.Prod'!$D10*'8.Prod'!$E10*'9.Var.Vente1'!F11 -> 0 | G11: ='8.Prod'!$D10*'8.Prod'!$E10*'9.Var.Vente1'!G11 -> 0 | H11: ='8.Prod'!$D10*'8.Prod'!$E10*'9.Var.Vente1'!H11 -> 0 | I11: ='8.Prod'!$D10*'8.Prod'!$E10*'9.Var.Vente1'!I11 -> 0 | J11: ='8.Prod'!$D10*'8.Prod'!$E10*'9.Var.Vente1'!J11 -> 0 | K11: ='8.Prod'!$D10*'8.Prod'!$E10*'9.Var.Vente1'!K11 -> 0 | ... R11: ='8.Prod'!$D10*'8.Prod'!$E10*'9.Var.Vente1'!R11 -> 0
A12: Total | D12: =SUM(D5:D11) -> #VALUE! | E12: =SUM(E5:E11) -> #VALUE! | F12: =SUM(F5:F11) -> #VALUE! | G12: =SUM(G5:G11) -> #VALUE! | H12: =SUM(H5:H11) -> #VALUE! | I12: =SUM(I5:I11) -> #VALUE! | J12: =SUM(J5:J11) -> #VALUE! | K12: =SUM(K5:K11) -> #VALUE! | ... R12: =SUM(R5:R11) -> #VALUE!

Sheet 11.Charges
A1: LISTE DES CHARGES DIRECTES ET INDIRECTES
A3: Type de charges | B3: Nom | C3: CODE | D3: Quantité | E3: Montant
A4: Achat de marchandises | B4: Achat de Tenue de luxe Homme | C4: AMA1 | D4: 1 | E4: 6000
A5: Achat de marchandises | B5: Achat de Tenue de luxe Femme | C5: AMA1 | D5: 1 | E5: 12000
A6: Achat de marchandises | B6: Achat de Prêt-à-porter homme | C6: AMA1 | D6: 1 | E6: 3000
A7: Achat de marchandises | B7: Achat de Prêt-à-porter femme | C7: AMA1 | D7: 1 | E7: 1500
A8: Achat de MP | C8: AMA2 | D8: 1
A9: Main d'œuvre directe vente | C9: MOD1 | D9: 1
A10: Main d'œuvre directe transformation | C10: MOD2 | D10: 1
A11: Main d'œuvre directe vente de services | C11: MOD3 | D11: 1
A12: Frais indirects de transformation | C12: FIF1 | D12: 1
A13: Frais indirects de vente | B13: Logistique Tenue de luxe Homme | C13: FIF2 | D13: 1 | E13: 200
A14: Frais indirects de vente | B14: Logistique Tenue de luxe Femme | C14: FIF2 | D14: 1 | E14: 400
A15: Frais indirects de vente | B15: Logistique Prêt-à-porter homme | C15: FIF2 | D15: 1 | E15: 100
A16: Frais indirects de vente | B16: Logistique Prêt-à-porter femme | C16: FIF2 | D16: 1 | E16: 50
A17: Frais indirects de vente | B17: Stockage Tenue de luxe Homme | C17: FIF2 | D17: 1 | E17: 400
A18: Frais indirects de vente | B18: Stockage Tenue de luxe Femme | C18: FIF2 | D18: 1 | E18: 800
A19: Frais indirects de vente | B19: Stockage Prêt-à-porter homme | C19: FIF2 | D19: 1 | E19: 200
A20: Frais indirects de vente | B20: Stockage Prêt-à-porter femme | C20: FIF2 | D20: 1 | E20: 100
A21: Frais indirects de vente | B21: Commission MP Tenue de luxe Homme | C21: FIF2 | D21: 1 | E21: 200
A22: Frais indirects de vente | B22: Commission MP Tenue de luxe Femme | C22: FIF2 | D22: 1 | E22: 400
A23: Frais indirects de vente | B23: Commission MP Prêt-à-porter homme | C23: FIF2 | D23: 1 | E23: 100
A24: Frais indirects de vente | B24: Commission MP Prêt-à-porter femme | C24: FIF2 | D24: 1 | E24: 50
A25: Frais indirects de vente de services | C25: FIF3 | D25: 1
A26: Salaires et Avantages | B26: Salaire personnel | C26: SAV1 | D26: 1 | E26: 0.22
A27: Taxe et redevance | B27: Timbre | C27: TXR1 | D27: 1 | E27: 0.0048
A28: Impôt sur les entreprises | B28: BIC | C28: IMP1 | D28: 1 | E28: 0.0307
A29: Action commerciale | B29: Sponsoring page réseaux sociaux | C29: MKT1 | D29: 1 | E29: 1900000
A30: Frais Généraux | B30: Frais administration | C30: FG1 | D30: 1 | E30: =15000+10000 -> 25000
A31: Energie/Electricité/ Eau | B31: Eau | C31: EEE1 | D31: 1 | E31: 82500
A32: Frais de transport | B32: Carburant | C32: FT1 | D32: 1 | E32: 50000
A33: Frais de communication | B33: Telephone / Internet | C33: MKT2 | D33: 1 | E33: =50000 -> 50000
A34: Publicité et Marketing | C34: FKT3 | D34: 1
A35: Location | B35: Loyer | C35: LOC1 | D35: 1 | E35: 250000
A36: Assurance | B36: Assurance voiture | C36: ASS1 | D36: 1 | E36: 12000
A37: Prestations et Honoraires | B37: Frais Infogérance | C37: PH1 | D37: 1 | E37: =370000+10000 -> 380000
A38: Autres provisions | C38: APR1 | D38: 1
A39: Amortissement Bureau | C39: AMR2 | D39: 1
A40: Amortissement Exploitation | B40: Amortissement équipement. | C40: AMR1 | D40: 1 | E40: 0.0351

Sheet 12.Char.Dir
A1: CHARGES INDIRECTES
D2: Charges mensuelles | P2: Charges annuelles
A3: Type de charges | B3: Charge | C3: CODE | D3: 1 | E3: 2 | F3: 3 | G3: 4 | H3: 5 | I3: 6 | J3: 7 | K3: 8 | L3: 9 | M3: 10 | N3: 11 | O3: 12 | P3: N | Q3: N+1 | R3: N+2
A4: ='11.Charges'!A4 -> Achat de marchandises | B4: ='11.Charges'!B4 -> Achat de Tenue de luxe Homme | C4: ='11.Charges'!C4 -> AMA1 | D4: ='11.Charges'!$D4*'11.Charges'!$E4*'9.Var.Vente1'!D$5 -> 360000 | E4: ='11.Charges'!$D4*'11.Charges'!$E4*'9.Var.Vente1'!E$5 -> 360000 | F4: ='11.Charges'!$D4*'11.Charges'!$E4*'9.Var.Vente1'!F$5 -> 360000 | G4: ='11.Charges'!$D4*'11.Charges'!$E4*'9.Var.Vente1'!G$5 -> 360000 | H4: ='11.Charges'!$D4*'11.Charges'!$E4*'9.Var.Vente1'!H$5 -> 360000 | I4: ='11.Charges'!$D4*'11.Charges'!$E4*'9.Var.Vente1'!I$5 -> 360000 | J4: ='11.Charges'!$D4*'11.Charges'!$E4*'9.Var.Vente1'!J$5 -> 360000 | K4: ='11.Charges'!$D4*'11.Charges'!$E4*'9.Var.Vente1'!K$5 -> 360000 | ... R4: ='11.Charges'!$D4*'11.Charges'!$E4*'9.Var.Vente1'!R$5 -> 5227200
A5: ='11.Charges'!A5 -> Achat de marchandises | B5: ='11.Charges'!B5 -> Achat de Tenue de luxe Femme | C5: ='11.Charges'!C5 -> AMA1 | D5: ='11.Charges'!$D5*'11.Charges'!$E5*'9.Var.Vente1'!D$5 -> 720000 | E5: ='11.Charges'!$D5*'11.Charges'!$E5*'9.Var.Vente1'!E$5 -> 720000 | F5: ='11.Charges'!$D5*'11.Charges'!$E5*'9.Var.Vente1'!F$5 -> 720000 | G5: ='11.Charges'!$D5*'11.Charges'!$E5*'9.Var.Vente1'!G$5 -> 720000 | H5: ='11.Charges'!$D5*'11.Charges'!$E5*'9.Var.Vente1'!H$5 -> 720000 | I5: ='11.Charges'!$D5*'11.Charges'!$E5*'9.Var.Vente1'!I$5 -> 720000 | J5: ='11.Charges'!$D5*'11.Charges'!$E5*'9.Var.Vente1'!J$5 -> 720000 | K5: ='11.Charges'!$D5*'11.Charges'!$E5*'9.Var.Vente1'!K$5 -> 720000 | ... R5: ='11.Charges'!$D5*'11.Charges'!$E5*'9.Var.Vente1'!R$5 -> 10454400
A6: ='11.Charges'!A6 -> Achat de marchandises | B6: ='11.Charges'!B6 -> Achat de Prêt-à-porter homme | C6: ='11.Charges'!C6 -> AMA1 | D6: ='11.Charges'!$D6*'11.Charges'!$E6*'9.Var.Vente1'!D$5 -> 180000 | E6: ='11.Charges'!$D6*'11.Charges'!$E6*'9.Var.Vente1'!E$5 -> 180000 | F6: ='11.Charges'!$D6*'11.Charges'!$E6*'9.Var.Vente1'!F$5 -> 180000 | G6: ='11.Charges'!$D6*'11.Charges'!$E6*'9.Var.Vente1'!G$5 -> 180000 | H6: ='11.Charges'!$D6*'11.Charges'!$E6*'9.Var.Vente1'!H$5 -> 180000 | I6: ='11.Charges'!$D6*'11.Charges'!$E6*'9.Var.Vente1'!I$5 -> 180000 | J6: ='11.Charges'!$D6*'11.Charges'!$E6*'9.Var.Vente1'!J$5 -> 180000 | K6: ='11.Charges'!$D6*'11.Charges'!$E6*'9.Var.Vente1'!K$5 -> 180000 | ... R6: ='11.Charges'!$D6*'11.Charges'!$E6*'9.Var.Vente1'!R$5 -> 2613600
A7: ='11.Charges'!A7 -> Achat de marchandises | B7: ='11.Charges'!B7 -> Achat de Prêt-à-porter femme | C7: ='11.Charges'!C7 -> AMA1 | D7: ='11.Charges'!$D7*'11.Charges'!$E7*'9.Var.Vente1'!D$5 -> 90000 | E7: ='11.Charges'!$D7*'11.Charges'!$E7*'9.Var.Vente1'!E$5 -> 90000 | F7: ='11.Charges'!$D7*'11.Charges'!$E7*'9.Var.Vente1'!F$5 -> 90000 | G7: ='11.Charges'!$D7*'11.Charges'!$E7*'9.Var.Vente1'!G$5 -> 90000 | H7: ='11.Charges'!$D7*'11.Charges'!$E7*'9.Var.Vente1'!H$5 -> 90000 | I7: ='11.Charges'!$D7*'11.Charges'!$E7*'9.Var.Vente1'!I$5 -> 90000 | J7: ='11.Charges'!$D7*'11.Charges'!$E7*'9.Var.Vente1'!J$5 -> 90000 | K7: ='11.Charges'!$D7*'11.Charges'!$E7*'9.Var.Vente1'!K$5 -> 90000 | ... R7: ='11.Charges'!$D7*'11.Charges'!$E7*'9.Var.Vente1'!R$5 -> 1306800
A8: ='11.Charges'!A8 -> Achat de MP | B8: ='11.Charges'!B8 -> 0 | C8: ='11.Charges'!C8 -> AMA2 | D8: ='11.Charges'!$E$8*'11.Charges'!$D$8*'9.Var.Vente1'!D9 -> 0 | E8: ='11.Charges'!$E$8*'11.Charges'!$D$8*'9.Var.Vente1'!E9 -> 0 | F8: ='11.Charges'!$E$8*'11.Charges'!$D$8*'9.Var.Vente1'!F9 -> 0 | G8: ='11.Charges'!$E$8*'11.Charges'!$D$8*'9.Var.Vente1'!G9 -> 0 | H8: ='11.Charges'!$E$8*'11.Charges'!$D$8*'9.Var.Vente1'!H9 -> 0 | I8: ='11.Charges'!$E$8*'11.Charges'!$D$8*'9.Var.Vente1'!I9 -> 0 | J8: ='11.Charges'!$E$8*'11.Charges'!$D$8*'9.Var.Vente1'!J9 -> 0 | K8: ='11.Charges'!$E$8*'11.Charges'!$D$8*'9.Var.Vente1'!K9 -> 0 | ... O8: ='11.Charges'!$E$8*'11.Charges'!$D$8*'9.Var.Vente1'!O9 -> 0 | P8: ='11.Charges'!$D8*'11.Charges'!$E8*'9.Var.Vente1'!P$5 -> 0 | Q8: ='11.Charges'!$D8*'11.Charges'!$E8*'9.Var.Vente1'!Q$5 -> 0 | R8: ='11.Charges'!$D8*'11.Charges'!$E8*'9.Var.Vente1'!R$5 -> 0
A9: ='11.Charges'!A9 -> Main d'œuvre directe vente | B9: ='11.Charges'!B9 -> 0 | C9: ='11.Charges'!C9 -> MOD1 | D9: ='11.Charges'!$E$9*'11.Charges'!$D$9*'9.Var.Vente1'!D5 -> 0 | E9: ='11.Charges'!$E$9*'11.Charges'!$D$9*'9.Var.Vente1'!E5 -> 0 | F9: ='11.Charges'!$E$9*'11.Charges'!$D$9*'9.Var.Vente1'!F5 -> 0 | G9: ='11.Charges'!$E$9*'11.Charges'!$D$9*'9.Var.Vente1'!G5 -> 0 | H9: ='11.Charges'!$E$9*'11.Charges'!$D$9*'9.Var.Vente1'!H5 -> 0 | I9: ='11.Charges'!$E$9*'11.Charges'!$D$9*'9.Var.Vente1'!I5 -> 0 | J9: ='11.Charges'!$E$9*'11.Charges'!$D$9*'9.Var.Vente1'!J5 -> 0 | K9: ='11.Charges'!$E$9*'11.Charges'!$D$9*'9.Var.Vente1'!K5 -> 0 | ... O9: ='11.Charges'!$E$9*'11.Charges'!$D$9*'9.Var.Vente1'!O5 -> 0 | P9: ='11.Charges'!$D9*'11.Charges'!$E9*'9.Var.Vente1'!P$5 -> 0 | Q9: ='11.Charges'!$D9*'11.Charges'!$E9*'9.Var.Vente1'!Q$5 -> 0 | R9: ='11.Charges'!$D9*'11.Charges'!$E9*'9.Var.Vente1'!R$5 -> 0
A10: ='11.Charges'!A10 -> Main d'œuvre directe transformation | B10: ='11.Charges'!B10 -> 0 | C10: ='11.Charges'!C10 -> MOD2 | D10: ='11.Charges'!$E$10*'11.Charges'!$D$10*'9.Var.Vente1'!D9 -> 0 | E10: ='11.Charges'!$E$10*'11.Charges'!$D$10*'9.Var.Vente1'!E9 -> 0 | F10: ='11.Charges'!$E$10*'11.Charges'!$D$10*'9.Var.Vente1'!F9 -> 0 | G10: ='11.Charges'!$E$10*'11.Charges'!$D$10*'9.Var.Vente1'!G9 -> 0 | H10: ='11.Charges'!$E$10*'11.Charges'!$D$10*'9.Var.Vente1'!H9 -> 0 | I10: ='11.Charges'!$E$10*'11.Charges'!$D$10*'9.Var.Vente1'!I9 -> 0 | J10: ='11.Charges'!$E$10*'11.Charges'!$D$10*'9.Var.Vente1'!J9 -> 0 | K10: ='11.Charges'!$E$10*'11.Charges'!$D$10*'9.Var.Vente1'!K9 -> 0 | ... O10: ='11.Charges'!$E$10*'11.Charges'!$D$10*'9.Var.Vente1'!O9 -> 0 | P10: ='11.Charges'!$D10*'11.Charges'!$E10*'9.Var.Vente1'!P$5 -> 0 | Q10: ='11.Charges'!$D10*'11.Charges'!$E10*'9.Var.Vente1'!Q$5 -> 0 | R10: ='11.Charges'!$D10*'11.Charges'!$E10*'9.Var.Vente1'!R$5 -> 0
A11: ='11.Charges'!A11 -> Main d'œuvre directe vente de services | B11: ='11.Charges'!B11 -> 0 | C11: ='11.Charges'!C11 -> MOD3 | D11: ='11.Charges'!$D$11*'11.Charges'!$E$11*'9.Var.Vente1'!D10 -> 0 | E11: ='11.Charges'!$D$11*'11.Charges'!$E$11*'9.Var.Vente1'!E10 -> 0 | F11: ='11.Charges'!$D$11*'11.Charges'!$E$11*'9.Var.Vente1'!F10 -> 0 | G11: ='11.Charges'!$D$11*'11.Charges'!$E$11*'9.Var.Vente1'!G10 -> 0 | H11: ='11.Charges'!$D$11*'11.Charges'!$E$11*'9.Var.Vente1'!H10 -> 0 | I11: ='11.Charges'!$D$11*'11.Charges'!$E$11*'9.Var.Vente1'!I10 -> 0 | J11: ='11.Charges'!$D$11*'11.Charges'!$E$11*'9.Var.Vente1'!J10 -> 0 | K11: ='11.Charges'!$D$11*'11.Charges'!$E$11*'9.Var.Vente1'!K10 -> 0 | ... O11: ='11.Charges'!$D$11*'11.Charges'!$E$11*'9.Var.Vente1'!O10 -> 0 | P11: ='11.Charges'!$D11*'11.Charges'!$E11*'9.Var.Vente1'!P$5 -> 0 | Q11: ='11.Charges'!$D11*'11.Charges'!$E11*'9.Var.Vente1'!Q$5 -> 0 | R11: ='11.Charges'!$D11*'11.Charges'!$E11*'9.Var.Vente1'!R$5 -> 0
A12: ='11.Charges'!A12 -> Frais indirects de transformation | B12: ='11.Charges'!B12 -> 0 | C12: ='11.Charges'!C12 -> FIF1 | D12: ='11.Charges'!$D$12*'11.Charges'!$E$12*'9.Var.Vente1'!D9 -> 0 | E12: ='11.Charges'!$D$12*'11.Charges'!$E$12*'9.Var.Vente1'!E9 -> 0 | F12: ='11.Charges'!$D$12*'11.Charges'!$E$12*'9.Var.Vente1'!F9 -> 0 | G12: ='11.Charges'!$D$12*'11.Charges'!$E$12*'9.Var.Vente1'!G9 -> 0 | H12: ='11.Charges'!$D$12*'11.Charges'!$E$12*'9.Var.Vente1'!H9 -> 0 | I12: ='11.Charges'!$D$12*'11.Charges'!$E$12*'9.Var.Vente1'!I9 -> 0 | J12: ='11.Charges'!$D$12*'11.Charges'!$E$12*'9.Var.Vente1'!J9 -> 0 | K12: ='11.Charges'!$D$12*'11.Charges'!$E$12*'9.Var.Vente1'!K9 -> 0 | ... O12: ='11.Charges'!$D$12*'11.Charges'!$E$12*'9.Var.Vente1'!O9 -> 0 | P12: ='11.Charges'!$D12*'11.Charges'!$E12*'9.Var.Vente1'!P$5 -> 0 | Q12: ='11.Charges'!$D12*'11.Charges'!$E12*'9.Var.Vente1'!Q$5 -> 0 | R12: ='11.Charges'!$D12*'11.Charges'!$E12*'9.Var.Vente1'!R$5 -> 0
A13: ='11.Charges'!A13 -> Frais indirects de vente | B13: ='11.Charges'!B13 -> Logistique Tenue de luxe Homme | C13: ='11.Charges'!C13 -> FIF2 | D13: ='11.Charges'!$D$13*'11.Charges'!$E$13*'9.Var.Vente1'!D5 -> 12000 | E13: ='11.Charges'!$D$13*'11.Charges'!$E$13*'9.Var.Vente1'!E5 -> 12000 | F13: ='11.Charges'!$D$13*'11.Charges'!$E$13*'9.Var.Vente1'!F5 -> 12000 | G13: ='11.Charges'!$D$13*'11.Charges'!$E$13*'9.Var.Vente1'!G5 -> 12000 | H13: ='11.Charges'!$D$13*'11.Charges'!$E$13*'9.Var.Vente1'!H5 -> 12000 | I13: ='11.Charges'!$D$13*'11.Charges'!$E$13*'9.Var.Vente1'!I5 -> 12000 | J13: ='11.Charges'!$D$13*'11.Charges'!$E$13*'9.Var.Vente1'!J5 -> 12000 | K13: ='11.Charges'!$D$13*'11.Charges'!$E$13*'9.Var.Vente1'!K5 -> 12000 | ... O13: ='11.Charges'!$D$13*'11.Charges'!$E$13*'9.Var.Vente1'!O5 -> 12000 | P13: ='11.Charges'!$D13*'11.Charges'!$E13*'9.Var.Vente1'!P$5 -> 144000 | Q13: ='11.Charges'!$D13*'11.Charges'!$E13*'9.Var.Vente1'!Q$5 -> 158400 | R13: ='11.Charges'!$D13*'11.Charges'!$E13*'9.Var.Vente1'!R$5 -> 174240
A14: ='11.Charges'!A14 -> Frais indirects de vente | B14: ='11.Charges'!B14 -> Logistique Tenue de luxe Femme | C14: ='11.Charges'!C14 -> FIF2 | D14: ='11.Charges'!$D$13*'11.Charges'!$E$13*'9.Var.Vente1'!D6 -> 22800 | E14: ='11.Charges'!$D$13*'11.Charges'!$E$13*'9.Var.Vente1'!E6 -> 22800 | F14: ='11.Charges'!$D$13*'11.Charges'!$E$13*'9.Var.Vente1'!F6 -> 22800 | G14: ='11.Charges'!$D$13*'11.Charges'!$E$13*'9.Var.Vente1'!G6 -> 22800 | H14: ='11.Charges'!$D$13*'11.Charges'!$E$13*'9.Var.Vente1'!H6 -> 22800 | I14: ='11.Charges'!$D$13*'11.Charges'!$E$13*'9.Var.Vente1'!I6 -> 22800 | J14: ='11.Charges'!$D$13*'11.Charges'!$E$13*'9.Var.Vente1'!J6 -> 22800 | K14: ='11.Charges'!$D$13*'11.Charges'!$E$13*'9.Var.Vente1'!K6 -> 22800 | ... O14: ='11.Charges'!$D$13*'11.Charges'!$E$13*'9.Var.Vente1'!O6 -> 22800 | P14: ='11.Charges'!$D14*'11.Charges'!$E14*'9.Var.Vente1'!P$5 -> 288000 | Q14: ='11.Charges'!$D14*'11.Charges'!$E14*'9.Var.Vente1'!Q$5 -> 316800 | R14: ='11.Charges'!$D14*'11.Charges'!$E14*'9.Var.Vente1'!R$5 -> 348480
